Workbook

Sheet Read Me
A1: PracticeLab Chart Pool Tracker
A2: What is in the pool, by topic and specialty, uploaded when, and who should practise on it · built 21 October 2026
B5: What this is
B6: The training team's working view of the live chart pool. It answers four questions: what do we have, where are the holes, is the build keeping up, and which charts should this cohort get.
B7: It is maintained by hand for now. One row per chart on the Chart Database sheet, whose first nine columns are the live charts table in table order — so when the application can export, that export pastes straight in with no reshaping. That is the whole reason the column order looks the way it does.
B9: The sheets, in the order you need them
B10: Leader Dashboard | C10: Twelve figures, the specialty table, and a list of where to look next. Read-only, all formulas. Start here.
B11: Chart Database | C11: Where the work is recorded. One row per chart. The only sheet most people type into.
B12: Category Dictionary | C12: The 111 topics and — the point of the sheet — the SHORT NAME to type in the application. Live counts and gaps beside each.
B13: Assignment Builder | C13: Set filters, read the count, filter the database. This is the selective-practice tool.
B14: Specialty Overview | C14: A headcount of charts per specialty, with the difficulty split.
B15: Monthly Trend | C15: Uploads by month and specialty, 24 months from an editable start.
B16: Recent Activity | C16: 7, 30 and 90 day windows, plus uploads by trainer.
B17: Field Conventions | C17: What goes in category and alias, and why. Read before briefing a trainer.
B18: Lists | C18: The source of every dropdown. Add a value here, never straight into a cell.
B20: The one thing to understand about counting
B21: A chart may carry several topics in one comma-separated category string, because that is how the application works. Two sheets therefore count two different things, and both are right:
B22: Specialty Overview counts CHARTS | C22: A chart filed as `Sepsis, AKI` counts once. Use it for a headcount and for % of target.
B23: Category Dictionary counts TOPIC COVERAGE | C23: The same chart counts under Sepsis AND under AKI, because it teaches both. Its total is therefore larger than the number of charts. Use it for gaps.
B24: Matching uses the same substring test the application uses, which is why the short names are guaranteed never to contain one another. `Respiratory` inside `Respiratory surgical` would have made one topic's count silently include another's; that is why the names read `Respiratory medical` and `Thoracic surgical`.
B26: Keeping it honest
B27: After every batch | C27: Add 1 to Times assigned and set Last assigned on the rows you used. Nothing else keeps the never-assigned reserve meaningful.
B28: Answer key | C28: Set it Yes once a key exists. An Active chart marked No can reach a batch and then fail to score, which is the one error this file is best placed to catch.
B29: Retiring | C29: Set status to Retired. Keep the row — deleting it loses the history of what left the pool and when.
B30: Capacity | C30: Formulas cover database rows 6 to 4005, about a third again over the 2,942-chart target. Paste past row 4005 and the dashboard quietly stops counting the overflow.
B32: Its relationship to the other two workbooks
B33: Chart Composition Taxonomy | C33: The standard: what the pool SHOULD contain, topic by topic, with weights and targets. This file's targets come from there.
B34: Chart Inventory Tracker | C34: The build programme: expected dates, FTE, slippage, issues. Deliberately a separate file, because it answers to a different audience on a different cadence.
B35: This file | C35: The live pool and day-to-day assignment, for the whole training team. All three import one topic module, so the taxonomy cannot differ between them.
B37: What it cannot do
B38: There are no native PivotTables — the tool that writes this file cannot create them. The summary views are formulas instead, which need no refresh and survive being emailed. For ad-hoc pivoting, select the Chart Database and insert a PivotTable; it is a flat table with a header row, which is all a pivot needs.
B39: It is not connected to the application. Nothing here reads or writes PracticeLab, and nothing in PracticeLab knows this file exists. The moment the application can export the charts table, the Chart Database sheet is where that export lands.

Sheet Leader Dashboard
A1: Chart pool — leader dashboard
A2: Everything is a formula over the Chart Database. Nothing on this sheet is typed. Built 21 October 2026.
A4: THE POOL
A5: Charts in the pool | B5: =COUNTIF('Chart Database'!$F$6:$F$4005,"Active") | C5: Active charts available to a batch right now.
A6: Target pool | B6: ='Specialty Overview'!$C$12 | C6: The sum of the seven specialty targets from the composition taxonomy.
A7: Pool complete | B7: =IF(B6=0,"NA",B5/B6) | C7: Active against target. Reads NA before a target exists.
A8: Retired | B8: =COUNTIF('Chart Database'!$F$6:$F$4005,"Retired") | C8: Kept as rows, not deleted, so the history of what left the pool survives.
A9: Cannot be graded | B9: =COUNTIFS('Chart Database'!$O$6:$O$4005,"No",'Chart Database'!$F$6:$F$4005,"Active") | C9: Active charts with no answer key. These can reach a batch and then cannot be scored.
A10: Multi-topic charts | B10: =COUNTIFS('Chart Database'!$J$6:$J$4005,">=2",'Chart Database'!$F$6:$F$4005,"Active") | C10: Carrying more than one category, so they cover more ground per chart.
A11: Never assigned | B11: =COUNTIFS('Chart Database'!$Q$6:$Q$4005,0,'Chart Database'!$F$6:$F$4005,"Active") | C11: Unseen by anyone — the reserve for assessments and reassessments.
A12: Charts with an off-list category | B12: =SUMPRODUCT(--('Chart Database'!$A$6:$A$4005<>""),--(N('Chart Database'!$K$6:$K$4005)<N('Chart Database'!$J$6:$J$4005))) | C12: Charts carrying a category name that is in no dictionary row. They count as charts but toward no topic's coverage, so they are invisible until registered.
A13: Name clashes in the dictionary | B13: =COUNTIF('Category Dictionary'!$K$5:$K$135,"CLASH*") | C13: A short name that contains or sits inside another in the same specialty. Both of their counts are wrong until it is renamed.
A14: Topics with nothing at all | B14: =COUNTIFS('Category Dictionary'!$H$5:$H$135,0,'Category Dictionary'!$D$5:$D$135,"<>") | C14: Of 111 topics, how many have no chart. The sourcing list, in one number.
A15: Topics below target | B15: =COUNTIFS('Category Dictionary'!$J$5:$J$135,">0",'Category Dictionary'!$D$5:$D$135,"<>") | C15: Topics with a gap of one chart or more.
A16: Uploaded this month | B16: =COUNTIFS('Chart Database'!$H$6:$H$4005,">="&DATE(YEAR(TODAY()),MONTH(TODAY()),1),'Chart Database'!$H$6:$H$4005,"<="&TODAY()) | C16: The build rate, measured rather than assumed.
A17: Uploaded last 90 days | B17: =COUNTIFS('Chart Database'!$H$6:$H$4005,">="&TODAY()-90,'Chart Database'!$H$6:$H$4005,"<="&TODAY()) | C17: A steadier read than one month, which one trainer's backlog can distort.
A18: Oldest active chart, days | B18: =SUMPRODUCT(MAX(('Chart Database'!$F$6:$F$4005="Active")*('Chart Database'!$H$6:$H$4005<>"")*(TODAY()-'Chart Database'!$H$6:$H$4005))) | C18: Days since the oldest chart was uploaded. Past about 540 it predates a code-set year.
A20: BY SPECIALTY
A21: Specialty | B21: Target | C21: Active | D21: % of target | E21: Beginner | F21: Intermediate | G21: Advanced | H21: No key | I21: Status
A22: IP-DRG | B22: ='Specialty Overview'!$C$5 | C22: ='Specialty Overview'!$D$5 | D22: ='Specialty Overview'!$G$5 | E22: ='Specialty Overview'!$H$5 | F22: ='Specialty Overview'!$I$5 | G22: ='Specialty Overview'!$J$5 | H22: ='Specialty Overview'!$K$5 | I22: ='Specialty Overview'!$N$5
A23: ED Facility | B23: ='Specialty Overview'!$C$6 | C23: ='Specialty Overview'!$D$6 | D23: ='Specialty Overview'!$G$6 | E23: ='Specialty Overview'!$H$6 | F23: ='Specialty Overview'!$I$6 | G23: ='Specialty Overview'!$J$6 | H23: ='Specialty Overview'!$K$6 | I23: ='Specialty Overview'!$N$6
A24: ED Profee | B24: ='Specialty Overview'!$C$7 | C24: ='Specialty Overview'!$D$7 | D24: ='Specialty Overview'!$G$7 | E24: ='Specialty Overview'!$H$7 | F24: ='Specialty Overview'!$I$7 | G24: ='Specialty Overview'!$J$7 | H24: ='Specialty Overview'!$K$7 | I24: ='Specialty Overview'!$N$7
A25: E/M | B25: ='Specialty Overview'!$C$8 | C25: ='Specialty Overview'!$D$8 | D25: ='Specialty Overview'!$G$8 | E25: ='Specialty Overview'!$H$8 | F25: ='Specialty Overview'!$I$8 | G25: ='Specialty Overview'!$J$8 | H25: ='Specialty Overview'!$K$8 | I25: ='Specialty Overview'!$N$8
A26: SDS | B26: ='Specialty Overview'!$C$9 | C26: ='Specialty Overview'!$D$9 | D26: ='Specialty Overview'!$G$9 | E26: ='Specialty Overview'!$H$9 | F26: ='Specialty Overview'!$I$9 | G26: ='Specialty Overview'!$J$9 | H26: ='Specialty Overview'!$K$9 | I26: ='Specialty Overview'!$N$9
A27: Surgery | B27: ='Specialty Overview'!$C$10 | C27: ='Specialty Overview'!$D$10 | D27: ='Specialty Overview'!$G$10 | E27: ='Specialty Overview'!$H$10 | F27: ='Specialty Overview'!$I$10 | G27: ='Specialty Overview'!$J$10 | H27: ='Specialty Overview'!$K$10 | I27: ='Specialty Overview'!$N$10
A28: ED Single Path | B28: ='Specialty Overview'!$C$11 | C28: ='Specialty Overview'!$D$11 | D28: ='Specialty Overview'!$G$11 | E28: ='Specialty Overview'!$H$11 | F28: ='Specialty Overview'!$I$11 | G28: ='Specialty Overview'!$J$11 | H28: ='Specialty Overview'!$K$11 | I28: ='Specialty Overview'!$N$11
A30: WHERE TO LOOK NEXT
A31: Topics with nothing at all → Category Dictionary, filter the In pool column to 0. That is the sourcing list.
A32: Charts that cannot be graded → Chart Database, filter Answer key to No. Each one can reach a batch and then fail to score.
A33: Who should practise what → Assignment Builder. Set the filters, then filter the database by Matches filter.
A34: Is the build keeping up → Monthly Trend. The data bar in the Total column is the rate.
A35: What changed lately → Recent Activity, by 7, 30 and 90 day windows and by trainer.
A36: What a trainer should type → Category Dictionary, the SHORT NAME column. That is the whole vocabulary.
A38: Pool complete divides ACTIVE charts by the taxonomy target. It is a headcount: a chart carrying three topics still counts once here, and three times on the Category Dictionary, which is why that sheet's total is larger.
A39: Every figure on this sheet reads Chart Database rows 6 to 4005. Paste beyond row 4005 and the dashboard silently stops counting the overflow, so extend the formulas rather than typing past the end.

Sheet Chart Database
A1: Chart Database
A2: One row per chart. The first nine columns are the live charts table, in order — paste an export straight in. Grey columns fill themselves.
A4: FROM THE APP | B4: FROM THE APP | C4: FROM THE APP | D4: FROM THE APP | E4: FROM THE APP | F4: FROM THE APP | G4: FROM THE APP | H4: FROM THE APP | I4: FROM THE APP | J4: AUTO | K4: AUTO | L4: AUTO | M4: AUTO | N4: AUTO | O4: WE MAINTAIN | P4: WE MAINTAIN | Q4: WE MAINTAIN | R4: WE MAINTAIN | S4: AUTO | T4: WE MAINTAIN
A5: chart_number | B5: specialty | C5: category | D5: difficulty | E5: alias | F5: status | G5: uploaded_by | H5: created_at | I5: view_count | J5: Topics on chart (auto) | K5: Recognised (auto) | L5: Primary topic (auto) | M5: Upload month (auto) | N5: Days in pool (auto) | O5: Answer key | P5: Error set versions | Q5: Times assigned | R5: Last assigned | S5: Matches filter (auto) | T5: Notes
J6: =IF($A6="","",LEN($C6)-LEN(SUBSTITUTE($C6,",",""))+1) | K6: =IF($A6="","",SUMPRODUCT(--ISNUMBER(SEARCH('Category Dictionary'!$D$5:$D$135&"",$C6)),--('Category Dictionary'!$D$5:$D$135<>""))) | L6: =IF($A6="","",TRIM(IF(ISERROR(FIND(",",$C6)),$C6,LEFT($C6,FIND(",",$C6)-1)))) | M6: =IF($H6="","",DATE(YEAR($H6),MONTH($H6),1)) | N6: =IF($H6="","",TODAY()-$H6) | S6: =IF($A6="","",AND(OR('Assignment Builder'!$B$5="",$B6='Assignment Builder'!$B$5),OR('Assignment Builder'!$B$6="",ISNUMBER(SEARCH('Assignment Builder'!$B$6,$C6))),OR('Assignment Builder'!$B$7="",'Assignment Builder'!$B$7=IFERROR(INDEX('Category Dictionary'!$C$5:$C$135,MATCH($L6,'Category Dictionary'!$D$5:$D$135,0)),"")),OR('Assignment Builder'!$B$8="",$D6='Assignment Builder'!$B$8),OR('Assignment Builder'!$B$9="",$F6='Assignment Builder'!$B$9),OR('Assignment Builder'!$B$10="",$O6='Assignment Builder'!$B$10),OR('Assignment Builder'!$B$11="",$H6>='Assignment Builder'!$B$11),OR('Assignment Builder'!$B$12="",N($Q6)<='Assignment Builder'!$B$12)))
J7: =IF($A7="","",LEN($C7)-LEN(SUBSTITUTE($C7,",",""))+1) | K7: =IF($A7="","",SUMPRODUCT(--ISNUMBER(SEARCH('Category Dictionary'!$D$5:$D$135&"",$C7)),--('Category Dictionary'!$D$5:$D$135<>""))) | L7: =IF($A7="","",TRIM(IF(ISERROR(FIND(",",$C7)),$C7,LEFT($C7,FIND(",",$C7)-1)))) | M7: =IF($H7="","",DATE(YEAR($H7),MONTH($H7),1)) | N7: =IF($H7="","",TODAY()-$H7) | S7: =IF($A7="","",AND(OR('Assignment Builder'!$B$5="",$B7='Assignment Builder'!$B$5),OR('Assignment Builder'!$B$6="",ISNUMBER(SEARCH('Assignment Builder'!$B$6,$C7))),OR('Assignment Builder'!$B$7="",'Assignment Builder'!$B$7=IFERROR(INDEX('Category Dictionary'!$C$5:$C$135,MATCH($L7,'Category Dictionary'!$D$5:$D$135,0)),"")),OR('Assignment Builder'!$B$8="",$D7='Assignment Builder'!$B$8),OR('Assignment Builder'!$B$9="",$F7='Assignment Builder'!$B$9),OR('Assignment Builder'!$B$10="",$O7='Assignment Builder'!$B$10),OR('Assignment Builder'!$B$11="",$H7>='Assignment Builder'!$B$11),OR('Assignment Builder'!$B$12="",N($Q7)<='Assignment Builder'!$B$12)))
J8: =IF($A8="","",LEN($C8)-LEN(SUBSTITUTE($C8,",",""))+1) | K8: =IF($A8="","",SUMPRODUCT(--ISNUMBER(SEARCH('Category Dictionary'!$D$5:$D$135&"",$C8)),--('Category Dictionary'!$D$5:$D$135<>""))) | L8: =IF($A8="","",TRIM(IF(ISERROR(FIND(",",$C8)),$C8,LEFT($C8,FIND(",",$C8)-1)))) | M8: =IF($H8="","",DATE(YEAR($H8),MONTH($H8),1)) | N8: =IF($H8="","",TODAY()-$H8) | S8: =IF($A8="","",AND(OR('Assignment Builder'!$B$5="",$B8='Assignment Builder'!$B$5),OR('Assignment Builder'!$B$6="",ISNUMBER(SEARCH('Assignment Builder'!$B$6,$C8))),OR('Assignment Builder'!$B$7="",'Assignment Builder'!$B$7=IFERROR(INDEX('Category Dictionary'!$C$5:$C$135,MATCH($L8,'Category Dictionary'!$D$5:$D$135,0)),"")),OR('Assignment Builder'!$B$8="",$D8='Assignment Builder'!$B$8),OR('Assignment Builder'!$B$9="",$F8='Assignment Builder'!$B$9),OR('Assignment Builder'!$B$10="",$O8='Assignment Builder'!$B$10),OR('Assignment Builder'!$B$11="",$H8>='Assignment Builder'!$B$11),OR('Assignment Builder'!$B$12="",N($Q8)<='Assignment Builder'!$B$12)))
J9: =IF($A9="","",LEN($C9)-LEN(SUBSTITUTE($C9,",",""))+1) | K9: =IF($A9="","",SUMPRODUCT(--ISNUMBER(SEARCH('Category Dictionary'!$D$5:$D$135&"",$C9)),--('Category Dictionary'!$D$5:$D$135<>""))) | L9: =IF($A9="","",TRIM(IF(ISERROR(FIND(",",$C9)),$C9,LEFT($C9,FIND(",",$C9)-1)))) | M9: =IF($H9="","",DATE(YEAR($H9),MONTH($H9),1)) | N9: =IF($H9="","",TODAY()-$H9) | S9: =IF($A9="","",AND(OR('Assignment Builder'!$B$5="",$B9='Assignment Builder'!$B$5),OR('Assignment Builder'!$B$6="",ISNUMBER(SEARCH('Assignment Builder'!$B$6,$C9))),OR('Assignment Builder'!$B$7="",'Assignment Builder'!$B$7=IFERROR(INDEX('Category Dictionary'!$C$5:$C$135,MATCH($L9,'Category Dictionary'!$D$5:$D$135,0)),"")),OR('Assignment Builder'!$B$8="",$D9='Assignment Builder'!$B$8),OR('Assignment Builder'!$B$9="",$F9='Assignment Builder'!$B$9),OR('Assignment Builder'!$B$10="",$O9='Assignment Builder'!$B$10),OR('Assignment Builder'!$B$11="",$H9>='Assignment Builder'!$B$11),OR('Assignment Builder'!$B$12="",N($Q9)<='Assignment Builder'!$B$12)))
J10: =IF($A10="","",LEN($C10)-LEN(SUBSTITUTE($C10,",",""))+1) | K10: =IF($A10="","",SUMPRODUCT(--ISNUMBER(SEARCH('Category Dictionary'!$D$5:$D$135&"",$C10)),--('Category Dictionary'!$D$5:$D$135<>""))) | L10: =IF($A10="","",TRIM(IF(ISERROR(FIND(",",$C10)),$C10,LEFT($C10,FIND(",",$C10)-1)))) | M10: =IF($H10="","",DATE(YEAR($H10),MONTH($H10),1)) | N10: =IF($H10="","",TODAY()-$H10) | S10: =IF($A10="","",AND(OR('Assignment Builder'!$B$5="",$B10='Assignment Builder'!$B$5),OR('Assignment Builder'!$B$6="",ISNUMBER(SEARCH('Assignment Builder'!$B$6,$C10))),OR('Assignment Builder'!$B$7="",'Assignment Builder'!$B$7=IFERROR(INDEX('Category Dictionary'!$C$5:$C$135,MATCH($L10,'Category Dictionary'!$D$5:$D$135,0)),"")),OR('Assignment Builder'!$B$8="",$D10='Assignment Builder'!$B$8),OR('Assignment Builder'!$B$9="",$F10='Assignment Builder'!$B$9),OR('Assignment Builder'!$B$10="",$O10='Assignment Builder'!$B$10),OR('Assignment Builder'!$B$11="",$H10>='Assignment Builder'!$B$11),OR('Assignment Builder'!$B$12="",N($Q10)<='Assignment Builder'!$B$12)))
J11: =IF($A11="","",LEN($C11)-LEN(SUBSTITUTE($C11,",",""))+1) | K11: =IF($A11="","",SUMPRODUCT(--ISNUMBER(SEARCH('Category Dictionary'!$D$5:$D$135&"",$C11)),--('Category Dictionary'!$D$5:$D$135<>""))) | L11: =IF($A11="","",TRIM(IF(ISERROR(FIND(",",$C11)),$C11,LEFT($C11,FIND(",",$C11)-1)))) | M11: =IF($H11="","",DATE(YEAR($H11),MONTH($H11),1)) | N11: =IF($H11="","",TODAY()-$H11) | S11: =IF($A11="","",AND(OR('Assignment Builder'!$B$5="",$B11='Assignment Builder'!$B$5),OR('Assignment Builder'!$B$6="",ISNUMBER(SEARCH('Assignment Builder'!$B$6,$C11))),OR('Assignment Builder'!$B$7="",'Assignment Builder'!$B$7=IFERROR(INDEX('Category Dictionary'!$C$5:$C$135,MATCH($L11,'Category Dictionary'!$D$5:$D$135,0)),"")),OR('Assignment Builder'!$B$8="",$D11='Assignment Builder'!$B$8),OR('Assignment Builder'!$B$9="",$F11='Assignment Builder'!$B$9),OR('Assignment Builder'!$B$10="",$O11='Assignment Builder'!$B$10),OR('Assignment Builder'!$B$11="",$H11>='Assignment Builder'!$B$11),OR('Assignment Builder'!$B$12="",N($Q11)<='Assignment Builder'!$B$12)))
J12: =IF($A12="","",LEN($C12)-LEN(SUBSTITUTE($C12,",",""))+1) | K12: =IF($A12="","",SUMPRODUCT(--ISNUMBER(SEARCH('Category Dictionary'!$D$5:$D$135&"",$C12)),--('Category Dictionary'!$D$5:$D$135<>""))) | L12: =IF($A12="","",TRIM(IF(ISERROR(FIND(",",$C12)),$C12,LEFT($C12,FIND(",",$C12)-1)))) | M12: =IF($H12="","",DATE(YEAR($H12),MONTH($H12),1)) | N12: =IF($H12="","",TODAY()-$H12) | S12: =IF($A12="","",AND(OR('Assignment Builder'!$B$5="",$B12='Assignment Builder'!$B$5),OR('Assignment Builder'!$B$6="",ISNUMBER(SEARCH('Assignment Builder'!$B$6,$C12))),OR('Assignment Builder'!$B$7="",'Assignment Builder'!$B$7=IFERROR(INDEX('Category Dictionary'!$C$5:$C$135,MATCH($L12,'Category Dictionary'!$D$5:$D$135,0)),"")),OR('Assignment Builder'!$B$8="",$D12='Assignment Builder'!$B$8),OR('Assignment Builder'!$B$9="",$F12='Assignment Builder'!$B$9),OR('Assignment Builder'!$B$10="",$O12='Assignment Builder'!$B$10),OR('Assignment Builder'!$B$11="",$H12>='Assignment Builder'!$B$11),OR('Assignment Builder'!$B$12="",N($Q12)<='Assignment Builder'!$B$12)))
J13: =IF($A13="","",LEN($C13)-LEN(SUBSTITUTE($C13,",",""))+1) | K13: =IF($A13="","",SUMPRODUCT(--ISNUMBER(SEARCH('Category Dictionary'!$D$5:$D$135&"",$C13)),--('Category Dictionary'!$D$5:$D$135<>""))) | L13: =IF($A13="","",TRIM(IF(ISERROR(FIND(",",$C13)),$C13,LEFT($C13,FIND(",",$C13)-1)))) | M13: =IF($H13="","",DATE(YEAR($H13),MONTH($H13),1)) | N13: =IF($H13="","",TODAY()-$H13) | S13: =IF($A13="","",AND(OR('Assignment Builder'!$B$5="",$B13='Assignment Builder'!$B$5),OR('Assignment Builder'!$B$6="",ISNUMBER(SEARCH('Assignment Builder'!$B$6,$C13))),OR('Assignment Builder'!$B$7="",'Assignment Builder'!$B$7=IFERROR(INDEX('Category Dictionary'!$C$5:$C$135,MATCH($L13,'Category Dictionary'!$D$5:$D$135,0)),"")),OR('Assignment Builder'!$B$8="",$D13='Assignment Builder'!$B$8),OR('Assignment Builder'!$B$9="",$F13='Assignment Builder'!$B$9),OR('Assignment Builder'!$B$10="",$O13='Assignment Builder'!$B$10),OR('Assignment Builder'!$B$11="",$H13>='Assignment Builder'!$B$11),OR('Assignment Builder'!$B$12="",N($Q13)<='Assignment Builder'!$B$12)))
J14: =IF($A14="","",LEN($C14)-LEN(SUBSTITUTE($C14,",",""))+1) | K14: =IF($A14="","",SUMPRODUCT(--ISNUMBER(SEARCH('Category Dictionary'!$D$5:$D$135&"",$C14)),--('Category Dictionary'!$D$5:$D$135<>""))) | L14: =IF($A14="","",TRIM(IF(ISERROR(FIND(",",$C14)),$C14,LEFT($C14,FIND(",",$C14)-1)))) | M14: =IF($H14="","",DATE(YEAR($H14),MONTH($H14),1)) | N14: =IF($H14="","",TODAY()-$H14) | S14: =IF($A14="","",AND(OR('Assignment Builder'!$B$5="",$B14='Assignment Builder'!$B$5),OR('Assignment Builder'!$B$6="",ISNUMBER(SEARCH('Assignment Builder'!$B$6,$C14))),OR('Assignment Builder'!$B$7="",'Assignment Builder'!$B$7=IFERROR(INDEX('Category Dictionary'!$C$5:$C$135,MATCH($L14,'Category Dictionary'!$D$5:$D$135,0)),"")),OR('Assignment Builder'!$B$8="",$D14='Assignment Builder'!$B$8),OR('Assignment Builder'!$B$9="",$F14='Assignment Builder'!$B$9),OR('Assignment Builder'!$B$10="",$O14='Assignment Builder'!$B$10),OR('Assignment Builder'!$B$11="",$H14>='Assignment Builder'!$B$11),OR('Assignment Builder'!$B$12="",N($Q14)<='Assignment Builder'!$B$12)))
J15: =IF($A15="","",LEN($C15)-LEN(SUBSTITUTE($C15,",",""))+1) | K15: =IF($A15="","",SUMPRODUCT(--ISNUMBER(SEARCH('Category Dictionary'!$D$5:$D$135&"",$C15)),--('Category Dictionary'!$D$5:$D$135<>""))) | L15: =IF($A15="","",TRIM(IF(ISERROR(FIND(",",$C15)),$C15,LEFT($C15,FIND(",",$C15)-1)))) | M15: =IF($H15="","",DATE(YEAR($H15),MONTH($H15),1)) | N15: =IF($H15="","",TODAY()-$H15) | S15: =IF($A15="","",AND(OR('Assignment Builder'!$B$5="",$B15='Assignment Builder'!$B$5),OR('Assignment Builder'!$B$6="",ISNUMBER(SEARCH('Assignment Builder'!$B$6,$C15))),OR('Assignment Builder'!$B$7="",'Assignment Builder'!$B$7=IFERROR(INDEX('Category Dictionary'!$C$5:$C$135,MATCH($L15,'Category Dictionary'!$D$5:$D$135,0)),"")),OR('Assignment Builder'!$B$8="",$D15='Assignment Builder'!$B$8),OR('Assignment Builder'!$B$9="",$F15='Assignment Builder'!$B$9),OR('Assignment Builder'!$B$10="",$O15='Assignment Builder'!$B$10),OR('Assignment Builder'!$B$11="",$H15>='Assignment Builder'!$B$11),OR('Assignment Builder'!$B$12="",N($Q15)<='Assignment Builder'!$B$12)))
J16: =IF($A16="","",LEN($C16)-LEN(SUBSTITUTE($C16,",",""))+1) | K16: =IF($A16="","",SUMPRODUCT(--ISNUMBER(SEARCH('Category Dictionary'!$D$5:$D$135&"",$C16)),--('Category Dictionary'!$D$5:$D$135<>""))) | L16: =IF($A16="","",TRIM(IF(ISERROR(FIND(",",$C16)),$C16,LEFT($C16,FIND(",",$C16)-1)))) | M16: =IF($H16="","",DATE(YEAR($H16),MONTH($H16),1)) | N16: =IF($H16="","",TODAY()-$H16) | S16: =IF($A16="","",AND(OR('Assignment Builder'!$B$5="",$B16='Assignment Builder'!$B$5),OR('Assignment Builder'!$B$6="",ISNUMBER(SEARCH('Assignment Builder'!$B$6,$C16))),OR('Assignment Builder'!$B$7="",'Assignment Builder'!$B$7=IFERROR(INDEX('Category Dictionary'!$C$5:$C$135,MATCH($L16,'Category Dictionary'!$D$5:$D$135,0)),"")),OR('Assignment Builder'!$B$8="",$D16='Assignment Builder'!$B$8),OR('Assignment Builder'!$B$9="",$F16='Assignment Builder'!$B$9),OR('Assignment Builder'!$B$10="",$O16='Assignment Builder'!$B$10),OR('Assignment Builder'!$B$11="",$H16>='Assignment Builder'!$B$11),OR('Assignment Builder'!$B$12="",N($Q16)<='Assignment Builder'!$B$12)))
J17: =IF($A17="","",LEN($C17)-LEN(SUBSTITUTE($C17,",",""))+1) | K17: =IF($A17="","",SUMPRODUCT(--ISNUMBER(SEARCH('Category Dictionary'!$D$5:$D$135&"",$C17)),--('Category Dictionary'!$D$5:$D$135<>""))) | L17: =IF($A17="","",TRIM(IF(ISERROR(FIND(",",$C17)),$C17,LEFT($C17,FIND(",",$C17)-1)))) | M17: =IF($H17="","",DATE(YEAR($H17),MONTH($H17),1)) | N17: =IF($H17="","",TODAY()-$H17) | S17: =IF($A17="","",AND(OR('Assignment Builder'!$B$5="",$B17='Assignment Builder'!$B$5),OR('Assignment Builder'!$B$6="",ISNUMBER(SEARCH('Assignment Builder'!$B$6,$C17))),OR('Assignment Builder'!$B$7="",'Assignment Builder'!$B$7=IFERROR(INDEX('Category Dictionary'!$C$5:$C$135,MATCH($L17,'Category Dictionary'!$D$5:$D$135,0)),"")),OR('Assignment Builder'!$B$8="",$D17='Assignment Builder'!$B$8),OR('Assignment Builder'!$B$9="",$F17='Assignment Builder'!$B$9),OR('Assignment Builder'!$B$10="",$O17='Assignment Builder'!$B$10),OR('Assignment Builder'!$B$11="",$H17>='Assignment Builder'!$B$11),OR('Assignment Builder'!$B$12="",N($Q17)<='Assignment Builder'!$B$12)))
... J4005: =IF($A4005="","",LEN($C4005)-LEN(SUBSTITUTE($C4005,",",""))+1) | K4005: =IF($A4005="","",SUMPRODUCT(--ISNUMBER(SEARCH('Category Dictionary'!$D$5:$D$135&"",$C4005)),--('Category Dictionary'!$D$5:$D$135<>""))) | L4005: =IF($A4005="","",TRIM(IF(ISERROR(FIND(",",$C4005)),$C4005,LEFT($C4005,FIND(",",$C4005)-1)))) | M4005: =IF($H4005="","",DATE(YEAR($H4005),MONTH($H4005),1)) | N4005: =IF($H4005="","",TODAY()-$H4005) | S4005: =IF($A4005="","",AND(OR('Assignment Builder'!$B$5="",$B4005='Assignment Builder'!$B$5),OR('Assignment Builder'!$B$6="",ISNUMBER(SEARCH('Assignment Builder'!$B$6,$C4005))),OR('Assignment Builder'!$B$7="",'Assignment Builder'!$B$7=IFERROR(INDEX('Category Dictionary'!$C$5:$C$135,MATCH($L4005,'Category Dictionary'!$D$5:$D$135,0)),"")),OR('Assignment Builder'!$B$8="",$D4005='Assignment Builder'!$B$8),OR('Assignment Builder'!$B$9="",$F4005='Assignment Builder'!$B$9),OR('Assignment Builder'!$B$10="",$O4005='Assignment Builder'!$B$10),OR('Assignment Builder'!$B$11="",$H4005>='Assignment Builder'!$B$11),OR('Assignment Builder'!$B$12="",N($Q4005)<='Assignment Builder'!$B$12)))

Sheet Category Dictionary
A1: Category Dictionary — what to type
A2: The controlled vocabulary the application does not have. Type the short name exactly as it appears here, on upload and when filtering. Rows below the 111 are yours to add.
A4: Specialty | B4: Topic ID | C4: Build priority | D4: SHORT NAME — type this | E4: Full topic (taxonomy) | F4: Coverage category | G4: Target charts | H4: In pool now | I4: % of target | J4: Gap | K4: Name check | L4: Notes
A5: IP-DRG | B5: IPD-01 | C5: P1 | D5: Vaginal delivery | E5: Vaginal delivery and complications of labour | F5: Medical DRGs | G5: 35 | H5: =COUNTIFS('Chart Database'!$B$6:$B$4005,$A5,'Chart Database'!$C$6:$C$4005,"*"&$D5&"*",'Chart Database'!$F$6:$F$4005,"Active") | I5: =IF($G5=0,"NA",H5/$G5) | J5: =$G5-H5 | K5: =IF($D5="","",IF(SUMPRODUCT(--($A$5:$A$135=$A5),--($D$5:$D$135<>""),--(ROW($D$5:$D$135)<>ROW()),--(ISNUMBER(SEARCH($D5,$D$5:$D$135))+ISNUMBER(SEARCH($D$5:$D$135&"",$D5))>0))>0,"CLASH — overlaps another name in this specialty","OK"))
A6: IP-DRG | B6: IPD-02 | C6: P1 | D6: Newborn | E6: Normal newborn and newborn with condition | F6: Medical DRGs | G6: 28 | H6: =COUNTIFS('Chart Database'!$B$6:$B$4005,$A6,'Chart Database'!$C$6:$C$4005,"*"&$D6&"*",'Chart Database'!$F$6:$F$4005,"Active") | I6: =IF($G6=0,"NA",H6/$G6) | J6: =$G6-H6 | K6: =IF($D6="","",IF(SUMPRODUCT(--($A$5:$A$135=$A6),--($D$5:$D$135<>""),--(ROW($D$5:$D$135)<>ROW()),--(ISNUMBER(SEARCH($D6,$D$5:$D$135))+ISNUMBER(SEARCH($D$5:$D$135&"",$D6))>0))>0,"CLASH — overlaps another name in this specialty","OK"))
A7: IP-DRG | B7: IPD-03 | C7: P1 | D7: Neonatal ICU | E7: Neonatal and NICU admissions | F7: Medical DRGs | G7: 14 | H7: =COUNTIFS('Chart Database'!$B$6:$B$4005,$A7,'Chart Database'!$C$6:$C$4005,"*"&$D7&"*",'Chart Database'!$F$6:$F$4005,"Active") | I7: =IF($G7=0,"NA",H7/$G7) | J7: =$G7-H7 | K7: =IF($D7="","",IF(SUMPRODUCT(--($A$5:$A$135=$A7),--($D$5:$D$135<>""),--(ROW($D$5:$D$135)<>ROW()),--(ISNUMBER(SEARCH($D7,$D$5:$D$135))+ISNUMBER(SEARCH($D$5:$D$135&"",$D7))>0))>0,"CLASH — overlaps another name in this specialty","OK"))
A8: IP-DRG | B8: IPD-04 | C8: P1 | D8: Peripartum medical | E8: Antepartum and postpartum medical admissions | F8: Medical DRGs | G8: 14 | H8: =COUNTIFS('Chart Database'!$B$6:$B$4005,$A8,'Chart Database'!$C$6:$C$4005,"*"&$D8&"*",'Chart Database'!$F$6:$F$4005,"Active") | I8: =IF($G8=0,"NA",H8/$G8) | J8: =$G8-H8 | K8: =IF($D8="","",IF(SUMPRODUCT(--($A$5:$A$135=$A8),--($D$5:$D$135<>""),--(ROW($D$5:$D$135)<>ROW()),--(ISNUMBER(SEARCH($D8,$D$5:$D$135))+ISNUMBER(SEARCH($D$5:$D$135&"",$D8))>0))>0,"CLASH — overlaps another name in this specialty","OK"))
A9: IP-DRG | B9: IPD-05 | C9: P2 | D9: GI medical | E9: Digestive medical — GI bleed, pancreatitis, obstruction | F9: Medical DRGs | G9: 42 | H9: =COUNTIFS('Chart Database'!$B$6:$B$4005,$A9,'Chart Database'!$C$6:$C$4005,"*"&$D9&"*",'Chart Database'!$F$6:$F$4005,"Active") | I9: =IF($G9=0,"NA",H9/$G9) | J9: =$G9-H9 | K9: =IF($D9="","",IF(SUMPRODUCT(--($A$5:$A$135=$A9),--($D$5:$D$135<>""),--(ROW($D$5:$D$135)<>ROW()),--(ISNUMBER(SEARCH($D9,$D$5:$D$135))+ISNUMBER(SEARCH($D$5:$D$135&"",$D9))>0))>0,"CLASH — overlaps another name in this specialty","OK"))
A10: IP-DRG | B10: IPD-06 | C10: P2 | D10: Respiratory medical | E10: Respiratory — pneumonia, COPD exacerbation, respiratory failure | F10: Medical DRGs | G10: 49 | H10: =COUNTIFS('Chart Database'!$B$6:$B$4005,$A10,'Chart Database'!$C$6:$C$4005,"*"&$D10&"*",'Chart Database'!$F$6:$F$4005,"Active") | I10: =IF($G10=0,"NA",H10/$G10) | J10: =$G10-H10 | K10: =IF($D10="","",IF(SUMPRODUCT(--($A$5:$A$135=$A10),--($D$5:$D$135<>""),--(ROW($D$5:$D$135)<>ROW()),--(ISNUMBER(SEARCH($D10,$D$5:$D$135))+ISNUMBER(SEARCH($D$5:$D$135&"",$D10))>0))>0,"CLASH — overlaps another name in this specialty","OK"))
A11: IP-DRG | B11: IPD-07 | C11: P2 | D11: Cardiac medical | E11: Circulatory medical — heart failure, AMI, arrhythmia | F11: Medical DRGs | G11: 42 | H11: =COUNTIFS('Chart Database'!$B$6:$B$4005,$A11,'Chart Database'!$C$6:$C$4005,"*"&$D11&"*",'Chart Database'!$F$6:$F$4005,"Active") | I11: =IF($G11=0,"NA",H11/$G11) | J11: =$G11-H11 | K11: =IF($D11="","",IF(SUMPRODUCT(--($A$5:$A$135=$A11),--($D$5:$D$135<>""),--(ROW($D$5:$D$135)<>ROW()),--(ISNUMBER(SEARCH($D11,$D$5:$D$135))+ISNUMBER(SEARCH($D$5:$D$135&"",$D11))>0))>0,"CLASH — overlaps another name in this specialty","OK"))
A12: IP-DRG | B12: IPD-08 | C12: P2 | D12: Sepsis | E12: Sepsis, severe sepsis and septic shock | F12: Medical DRGs | G12: 49 | H12: =COUNTIFS('Chart Database'!$B$6:$B$4005,$A12,'Chart Database'!$C$6:$C$4005,"*"&$D12&"*",'Chart Database'!$F$6:$F$4005,"Active") | I12: =IF($G12=0,"NA",H12/$G12) | J12: =$G12-H12 | K12: =IF($D12="","",IF(SUMPRODUCT(--($A$5:$A$135=$A12),--($D$5:$D$135<>""),--(ROW($D$5:$D$135)<>ROW()),--(ISNUMBER(SEARCH($D12,$D$5:$D$135))+ISNUMBER(SEARCH($D$5:$D$135&"",$D12))>0))>0,"CLASH — overlaps another name in this specialty","OK"))
A13: IP-DRG | B13: IPD-09 | C13: P2 | D13: Neuro medical | E13: Nervous system medical — CVA, TIA, intracranial haemorrhage | F13: Medical DRGs | G13: 28 | H13: =COUNTIFS('Chart Database'!$B$6:$B$4005,$A13,'Chart Database'!$C$6:$C$4005,"*"&$D13&"*",'Chart Database'!$F$6:$F$4005,"Active") | I13: =IF($G13=0,"NA",H13/$G13) | J13: =$G13-H13 | K13: =IF($D13="","",IF(SUMPRODUCT(--($A$5:$A$135=$A13),--($D$5:$D$135<>""),--(ROW($D$5:$D$135)<>ROW()),--(ISNUMBER(SEARCH($D13,$D$5:$D$135))+ISNUMBER(SEARCH($D$5:$D$135&"",$D13))>0))>0,"CLASH — overlaps another name in this specialty","OK"))
A14: IP-DRG | B14: IPD-10 | C14: P2 | D14: Renal | E14: Kidney and urinary — AKI, CKD, UTI | F14: Medical DRGs | G14: 21 | H14: =COUNTIFS('Chart Database'!$B$6:$B$4005,$A14,'Chart Database'!$C$6:$C$4005,"*"&$D14&"*",'Chart Database'!$F$6:$F$4005,"Active") | I14: =IF($G14=0,"NA",H14/$G14) | J14: =$G14-H14 | K14: =IF($D14="","",IF(SUMPRODUCT(--($A$5:$A$135=$A14),--($D$5:$D$135<>""),--(ROW($D$5:$D$135)<>ROW()),--(ISNUMBER(SEARCH($D14,$D$5:$D$135))+ISNUMBER(SEARCH($D$5:$D$135&"",$D14))>0))>0,"CLASH — overlaps another name in this specialty","OK"))
A15: IP-DRG | B15: IPD-11 | C15: P2 | D15: Endocrine | E15: Endocrine and metabolic — DKA, malnutrition, electrolyte disorders | F15: Medical DRGs | G15: 21 | H15: =COUNTIFS('Chart Database'!$B$6:$B$4005,$A15,'Chart Database'!$C$6:$C$4005,"*"&$D15&"*",'Chart Database'!$F$6:$F$4005,"Active") | I15: =IF($G15=0,"NA",H15/$G15) | J15: =$G15-H15 | K15: =IF($D15="","",IF(SUMPRODUCT(--($A$5:$A$135=$A15),--($D$5:$D$135<>""),--(ROW($D$5:$D$135)<>ROW()),--(ISNUMBER(SEARCH($D15,$D$5:$D$135))+ISNUMBER(SEARCH($D$5:$D$135&"",$D15))>0))>0,"CLASH — overlaps another name in this specialty","OK"))
A16: IP-DRG | B16: IPD-12 | C16: P2 | D16: Heme onc | E16: Haematology and oncology — medical admissions | F16: Medical DRGs | G16: 21 | H16: =COUNTIFS('Chart Database'!$B$6:$B$4005,$A16,'Chart Database'!$C$6:$C$4005,"*"&$D16&"*",'Chart Database'!$F$6:$F$4005,"Active") | I16: =IF($G16=0,"NA",H16/$G16) | J16: =$G16-H16 | K16: =IF($D16="","",IF(SUMPRODUCT(--($A$5:$A$135=$A16),--($D$5:$D$135<>""),--(ROW($D$5:$D$135)<>ROW()),--(ISNUMBER(SEARCH($D16,$D$5:$D$135))+ISNUMBER(SEARCH($D$5:$D$135&"",$D16))>0))>0,"CLASH — overlaps another name in this specialty","OK"))
... A115: ED Single Path | B115: ESP-08 | C115: P3 | D115: SP divergence | E115: Facility and professional level divergence | F115: Cross-cutting | G115: 12 | H115: =COUNTIFS('Chart Database'!$B$6:$B$4005,$A115,'Chart Database'!$C$6:$C$4005,"*"&$D115&"*",'Chart Database'!$F$6:$F$4005,"Active") | I115: =IF($G115=0,"NA",H115/$G115) | J115: =$G115-H115 | K115: =IF($D115="","",IF(SUMPRODUCT(--($A$5:$A$135=$A115),--($D$5:$D$135<>""),--(ROW($D$5:$D$135)<>ROW()),--(ISNUMBER(SEARCH($D115,$D$5:$D$135))+ISNUMBER(SEARCH($D$5:$D$135&"",$D115))>0))>0,"CLASH — overlaps another name in this specialty","OK"))
B116: — | C116: P2 | E116: Added by the team — not in the composition taxonomy | H116: =IF($D116="","",COUNTIFS('Chart Database'!$B$6:$B$4005,$A116,'Chart Database'!$C$6:$C$4005,"*"&$D116&"*",'Chart Database'!$F$6:$F$4005,"Active")) | I116: =IF(OR($D116="",$G116=""),"NA",IF($G116=0,"NA",H116/$G116)) | J116: =IF(OR($D116="",$G116=""),"",$G116-H116) | K116: =IF($D116="","",IF(SUMPRODUCT(--($A$5:$A$135=$A116),--($D$5:$D$135<>""),--(ROW($D$5:$D$135)<>ROW()),--(ISNUMBER(SEARCH($D116,$D$5:$D$135))+ISNUMBER(SEARCH($D$5:$D$135&"",$D116))>0))>0,"CLASH — overlaps another name in this specialty","OK"))
B117: — | C117: P2 | E117: Added by the team — not in the composition taxonomy | H117: =IF($D117="","",COUNTIFS('Chart Database'!$B$6:$B$4005,$A117,'Chart Database'!$C$6:$C$4005,"*"&$D117&"*",'Chart Database'!$F$6:$F$4005,"Active")) | I117: =IF(OR($D117="",$G117=""),"NA",IF($G117=0,"NA",H117/$G117)) | J117: =IF(OR($D117="",$G117=""),"",$G117-H117) | K117: =IF($D117="","",IF(SUMPRODUCT(--($A$5:$A$135=$A117),--($D$5:$D$135<>""),--(ROW($D$5:$D$135)<>ROW()),--(ISNUMBER(SEARCH($D117,$D$5:$D$135))+ISNUMBER(SEARCH($D$5:$D$135&"",$D117))>0))>0,"CLASH — overlaps another name in this specialty","OK"))
B118: — | C118: P2 | E118: Added by the team — not in the composition taxonomy | H118: =IF($D118="","",COUNTIFS('Chart Database'!$B$6:$B$4005,$A118,'Chart Database'!$C$6:$C$4005,"*"&$D118&"*",'Chart Database'!$F$6:$F$4005,"Active")) | I118: =IF(OR($D118="",$G118=""),"NA",IF($G118=0,"NA",H118/$G118)) | J118: =IF(OR($D118="",$G118=""),"",$G118-H118) | K118: =IF($D118="","",IF(SUMPRODUCT(--($A$5:$A$135=$A118),--($D$5:$D$135<>""),--(ROW($D$5:$D$135)<>ROW()),--(ISNUMBER(SEARCH($D118,$D$5:$D$135))+ISNUMBER(SEARCH($D$5:$D$135&"",$D118))>0))>0,"CLASH — overlaps another name in this specialty","OK"))
B119: — | C119: P2 | E119: Added by the team — not in the composition taxonomy | H119: =IF($D119="","",COUNTIFS('Chart Database'!$B$6:$B$4005,$A119,'Chart Database'!$C$6:$C$4005,"*"&$D119&"*",'Chart Database'!$F$6:$F$4005,"Active")) | I119: =IF(OR($D119="",$G119=""),"NA",IF($G119=0,"NA",H119/$G119)) | J119: =IF(OR($D119="",$G119=""),"",$G119-H119) | K119: =IF($D119="","",IF(SUMPRODUCT(--($A$5:$A$135=$A119),--($D$5:$D$135<>""),--(ROW($D$5:$D$135)<>ROW()),--(ISNUMBER(SEARCH($D119,$D$5:$D$135))+ISNUMBER(SEARCH($D$5:$D$135&"",$D119))>0))>0,"CLASH — overlaps another name in this specialty","OK"))
B120: — | C120: P2 | E120: Added by the team — not in the composition taxonomy | H120: =IF($D120="","",COUNTIFS('Chart Database'!$B$6:$B$4005,$A120,'Chart Database'!$C$6:$C$4005,"*"&$D120&"*",'Chart Database'!$F$6:$F$4005,"Active")) | I120: =IF(OR($D120="",$G120=""),"NA",IF($G120=0,"NA",H120/$G120)) | J120: =IF(OR($D120="",$G120=""),"",$G120-H120) | K120: =IF($D120="","",IF(SUMPRODUCT(--($A$5:$A$135=$A120),--($D$5:$D$135<>""),--(ROW($D$5:$D$135)<>ROW()),--(ISNUMBER(SEARCH($D120,$D$5:$D$135))+ISNUMBER(SEARCH($D$5:$D$135&"",$D120))>0))>0,"CLASH — overlaps another name in this specialty","OK"))
B121: — | C121: P2 | E121: Added by the team — not in the composition taxonomy | H121: =IF($D121="","",COUNTIFS('Chart Database'!$B$6:$B$4005,$A121,'Chart Database'!$C$6:$C$4005,"*"&$D121&"*",'Chart Database'!$F$6:$F$4005,"Active")) | I121: =IF(OR($D121="",$G121=""),"NA",IF($G121=0,"NA",H121/$G121)) | J121: =IF(OR($D121="",$G121=""),"",$G121-H121) | K121: =IF($D121="","",IF(SUMPRODUCT(--($A$5:$A$135=$A121),--($D$5:$D$135<>""),--(ROW($D$5:$D$135)<>ROW()),--(ISNUMBER(SEARCH($D121,$D$5:$D$135))+ISNUMBER(SEARCH($D$5:$D$135&"",$D121))>0))>0,"CLASH — overlaps another name in this specialty","OK"))
B122: — | C122: P2 | E122: Added by the team — not in the composition taxonomy | H122: =IF($D122="","",COUNTIFS('Chart Database'!$B$6:$B$4005,$A122,'Chart Database'!$C$6:$C$4005,"*"&$D122&"*",'Chart Database'!$F$6:$F$4005,"Active")) | I122: =IF(OR($D122="",$G122=""),"NA",IF($G122=0,"NA",H122/$G122)) | J122: =IF(OR($D122="",$G122=""),"",$G122-H122) | K122: =IF($D122="","",IF(SUMPRODUCT(--($A$5:$A$135=$A122),--($D$5:$D$135<>""),--(ROW($D$5:$D$135)<>ROW()),--(ISNUMBER(SEARCH($D122,$D$5:$D$135))+ISNUMBER(SEARCH($D$5:$D$135&"",$D122))>0))>0,"CLASH — overlaps another name in this specialty","OK"))
B123: — | C123: P2 | E123: Added by the team — not in the composition taxonomy | H123: =IF($D123="","",COUNTIFS('Chart Database'!$B$6:$B$4005,$A123,'Chart Database'!$C$6:$C$4005,"*"&$D123&"*",'Chart Database'!$F$6:$F$4005,"Active")) | I123: =IF(OR($D123="",$G123=""),"NA",IF($G123=0,"NA",H123/$G123)) | J123: =IF(OR($D123="",$G123=""),"",$G123-H123) | K123: =IF($D123="","",IF(SUMPRODUCT(--($A$5:$A$135=$A123),--($D$5:$D$135<>""),--(ROW($D$5:$D$135)<>ROW()),--(ISNUMBER(SEARCH($D123,$D$5:$D$135))+ISNUMBER(SEARCH($D$5:$D$135&"",$D123))>0))>0,"CLASH — overlaps another name in this specialty","OK"))
B124: — | C124: P2 | E124: Added by the team — not in the composition taxonomy | H124: =IF($D124="","",COUNTIFS('Chart Database'!$B$6:$B$4005,$A124,'Chart Database'!$C$6:$C$4005,"*"&$D124&"*",'Chart Database'!$F$6:$F$4005,"Active")) | I124: =IF(OR($D124="",$G124=""),"NA",IF($G124=0,"NA",H124/$G124)) | J124: =IF(OR($D124="",$G124=""),"",$G124-H124) | K124: =IF($D124="","",IF(SUMPRODUCT(--($A$5:$A$135=$A124),--($D$5:$D$135<>""),--(ROW($D$5:$D$135)<>ROW()),--(ISNUMBER(SEARCH($D124,$D$5:$D$135))+ISNUMBER(SEARCH($D$5:$D$135&"",$D124))>0))>0,"CLASH — overlaps another name in this specialty","OK"))
B125: — | C125: P2 | E125: Added by the team — not in the composition taxonomy | H125: =IF($D125="","",COUNTIFS('Chart Database'!$B$6:$B$4005,$A125,'Chart Database'!$C$6:$C$4005,"*"&$D125&"*",'Chart Database'!$F$6:$F$4005,"Active")) | I125: =IF(OR($D125="",$G125=""),"NA",IF($G125=0,"NA",H125/$G125)) | J125: =IF(OR($D125="",$G125=""),"",$G125-H125) | K125: =IF($D125="","",IF(SUMPRODUCT(--($A$5:$A$135=$A125),--($D$5:$D$135<>""),--(ROW($D$5:$D$135)<>ROW()),--(ISNUMBER(SEARCH($D125,$D$5:$D$135))+ISNUMBER(SEARCH($D$5:$D$135&"",$D125))>0))>0,"CLASH — overlaps another name in this specialty","OK"))
B126: — | C126: P2 | E126: Added by the team — not in the composition taxonomy | H126: =IF($D126="","",COUNTIFS('Chart Database'!$B$6:$B$4005,$A126,'Chart Database'!$C$6:$C$4005,"*"&$D126&"*",'Chart Database'!$F$6:$F$4005,"Active")) | I126: =IF(OR($D126="",$G126=""),"NA",IF($G126=0,"NA",H126/$G126)) | J126: =IF(OR($D126="",$G126=""),"",$G126-H126) | K126: =IF($D126="","",IF(SUMPRODUCT(--($A$5:$A$135=$A126),--($D$5:$D$135<>""),--(ROW($D$5:$D$135)<>ROW()),--(ISNUMBER(SEARCH($D126,$D$5:$D$135))+ISNUMBER(SEARCH($D$5:$D$135&"",$D126))>0))>0,"CLASH — overlaps another name in this specialty","OK"))
B127: — | C127: P2 | E127: Added by the team — not in the composition taxonomy | H127: =IF($D127="","",COUNTIFS('Chart Database'!$B$6:$B$4005,$A127,'Chart Database'!$C$6:$C$4005,"*"&$D127&"*",'Chart Database'!$F$6:$F$4005,"Active")) | I127: =IF(OR($D127="",$G127=""),"NA",IF($G127=0,"NA",H127/$G127)) | J127: =IF(OR($D127="",$G127=""),"",$G127-H127) | K127: =IF($D127="","",IF(SUMPRODUCT(--($A$5:$A$135=$A127),--($D$5:$D$135<>""),--(ROW($D$5:$D$135)<>ROW()),--(ISNUMBER(SEARCH($D127,$D$5:$D$135))+ISNUMBER(SEARCH($D$5:$D$135&"",$D127))>0))>0,"CLASH — overlaps another name in this specialty","OK"))
... B135: — | C135: P2 | E135: Added by the team — not in the composition taxonomy | H135: =IF($D135="","",COUNTIFS('Chart Database'!$B$6:$B$4005,$A135,'Chart Database'!$C$6:$C$4005,"*"&$D135&"*",'Chart Database'!$F$6:$F$4005,"Active")) | I135: =IF(OR($D135="",$G135=""),"NA",IF($G135=0,"NA",H135/$G135)) | J135: =IF(OR($D135="",$G135=""),"",$G135-H135) | K135: =IF($D135="","",IF(SUMPRODUCT(--($A$5:$A$135=$A135),--($D$5:$D$135<>""),--(ROW($D$5:$D$135)<>ROW()),--(ISNUMBER(SEARCH($D135,$D$5:$D$135))+ISNUMBER(SEARCH($D$5:$D$135&"",$D135))>0))>0,"CLASH — overlaps another name in this specialty","OK"))
A136: TOTAL | G136: =SUM(G5:G135) | H136: =SUM(H5:H135) | I136: =IF(G136=0,"NA",H136/G136) | J136: =G136-H136 | K136: =COUNTIF(K5:K135,"CLASH*")&" name clash(es)"
A138: In pool now counts ACTIVE charts whose category contains this short name, which is how the application matches. A chart filed as "Sepsis, Renal" counts under both Sepsis and Renal — correctly, because it teaches both.
A139: A consequence worth knowing: the In pool column can sum to more than the number of charts, because a multi-topic chart is counted under each topic it carries. Use Specialty Overview for a headcount of charts and this sheet for coverage of topics.
A140: THE LAST 20 ROWS ARE YOURS. To track a topic the taxonomy does not have, type its specialty and a short name in the shaded cells; a target is optional and the coverage columns read NA without one. The name is counted from that moment, and the Leader Dashboard stops reporting charts carrying it as unrecognised.
A141: Name check is the one guard that cannot be skipped. Because the application matches by substring, a name that contains or sits inside another name in the same specialty makes both counts wrong — "Respiratory" would pick up every "Respiratory surgical" chart. Pick a name that reads CLASH again until it reads OK.
A142: A topic added here has no place in the composition taxonomy, so it carries no weight and no agreed target. If it turns out to be permanent, it belongs in that workbook properly — which means taking its share of charts from a sibling topic, since the weights must still sum to the HC parent percentage.

Sheet Assignment Builder
A1: Assignment Builder
A2: Set the filters, read the count, then filter the Chart Database by its last column. Nothing to write.
A4: FILTERS — leave a cell blank to ignore it
A5: Specialty | D5: Blank means every specialty.
A6: Category contains | D6: A short name from the Category Dictionary, e.g. Sepsis. Matches charts carrying it among several, exactly as the app does.
A7: Build priority | D7: P1 to P4. For a cohort that should meet the foundation topics first.
A8: Difficulty | D8: Beginner, Intermediate or Advanced.
A9: Status | B9: Active | D9: Active unless you are deliberately reviewing retired charts.
A10: Answer key required | B10: Yes | D10: Yes keeps only charts that can be graded. Blank is how an ungradeable chart reaches a batch.
A11: Uploaded on or after | D11: A date. Use to assign only recently refreshed material.
A12: Max times already assigned | D12: A number. 0 finds charts nobody has had yet. Blank ignores usage.
A14: RESULT
A15: Charts matching | B15: =COUNTIF('Chart Database'!$S$6:$S$4005,TRUE) | D15: How many charts in the pool satisfy every filter set above.
A16: of which never assigned | B16: =COUNTIFS('Chart Database'!$S$6:$S$4005,TRUE,'Chart Database'!$Q$6:$Q$4005,0) | D16: Unseen charts — what an assessment or a post-QIP reassessment needs.
A17: Distinct topics covered | B17: =SUMPRODUCT(--(COUNTIFS('Chart Database'!$S$6:$S$4005,TRUE,'Chart Database'!$C$6:$C$4005,"*"&'Category Dictionary'!$D$5:$D$135&"*")>0)) | D17: How many of the 111 topics the matching set touches. A batch drawn from one topic trains one thing.
A19: HOW TO GET THE LIST
A20: 1. Set the filters above. Only the cells you fill narrow the result.
A21: 2. Open Chart Database. Use the filter arrow on the last column, Matches filter, and tick TRUE.
A22: 3. The visible rows are the assignment set. Copy the chart_number column into the batch.
A23: 4. In the app, type the short name into the category filter — the same text you used in step 1.
A24: 5. Afterwards add 1 to Times assigned on those rows and set Last assigned. That is what keeps 'never assigned' honest.
A26: The count is live, so widen a filter until the number is workable rather than guessing. A count of zero means the pool cannot serve that request, which is itself the answer and the gap to take to sourcing.
A27: Category contains uses the same substring match the application uses, so a chart filed as "Sepsis, AKI" is found by a filter of either. That is why the short names are guaranteed never to contain one another — otherwise one topic's set would quietly include another's.
A28: Why a filter column and not a list that writes itself: a self-populating list needs the dynamic array functions only recent Excel has, and this file goes round a team on whatever version they run. The filter arrow works everywhere.

Sheet Specialty Overview
A1: Specialty Overview
A2: A headcount of charts, not of topics. Every figure a formula over the Chart Database.
A4: Specialty | B4: Prefix | C4: Target pool | D4: Active | E4: Retired | F4: Total rows | G4: % of target | H4: Beginner | I4: Intermediate | J4: Advanced | K4: No answer key | L4: Added last 30 days | M4: Never assigned | N4: Reading
A5: IP-DRG | B5: IP | C5: 693 | D5: =COUNTIFS('Chart Database'!$B$6:$B$4005,$A5,'Chart Database'!$F$6:$F$4005,"Active") | E5: =COUNTIFS('Chart Database'!$B$6:$B$4005,$A5,'Chart Database'!$F$6:$F$4005,"Retired") | F5: =COUNTIF('Chart Database'!$B$6:$B$4005,$A5) | G5: =IF($C5=0,"NA",D5/$C5) | H5: =COUNTIFS('Chart Database'!$B$6:$B$4005,$A5,'Chart Database'!$D$6:$D$4005,"Beginner",'Chart Database'!$F$6:$F$4005,"Active") | I5: =COUNTIFS('Chart Database'!$B$6:$B$4005,$A5,'Chart Database'!$D$6:$D$4005,"Intermediate",'Chart Database'!$F$6:$F$4005,"Active") | J5: =COUNTIFS('Chart Database'!$B$6:$B$4005,$A5,'Chart Database'!$D$6:$D$4005,"Advanced",'Chart Database'!$F$6:$F$4005,"Active") | K5: =COUNTIFS('Chart Database'!$B$6:$B$4005,$A5,'Chart Database'!$O$6:$O$4005,"No",'Chart Database'!$F$6:$F$4005,"Active") | L5: =COUNTIFS('Chart Database'!$B$6:$B$4005,$A5,'Chart Database'!$H$6:$H$4005,">="&TODAY()-30,'Chart Database'!$H$6:$H$4005,"<="&TODAY()) | M5: =COUNTIFS('Chart Database'!$B$6:$B$4005,$A5,'Chart Database'!$Q$6:$Q$4005,0,'Chart Database'!$F$6:$F$4005,"Active") | N5: =IF(D5=0,"Nothing in the pool yet",IF(D5>=C5,"At target",IF(K5>0,K5&" chart(s) cannot be graded",IF(D5/C5<0.5,"Under half built","Building"))))
A6: ED Facility | B6: ED | C6: 704 | D6: =COUNTIFS('Chart Database'!$B$6:$B$4005,$A6,'Chart Database'!$F$6:$F$4005,"Active") | E6: =COUNTIFS('Chart Database'!$B$6:$B$4005,$A6,'Chart Database'!$F$6:$F$4005,"Retired") | F6: =COUNTIF('Chart Database'!$B$6:$B$4005,$A6) | G6: =IF($C6=0,"NA",D6/$C6) | H6: =COUNTIFS('Chart Database'!$B$6:$B$4005,$A6,'Chart Database'!$D$6:$D$4005,"Beginner",'Chart Database'!$F$6:$F$4005,"Active") | I6: =COUNTIFS('Chart Database'!$B$6:$B$4005,$A6,'Chart Database'!$D$6:$D$4005,"Intermediate",'Chart Database'!$F$6:$F$4005,"Active") | J6: =COUNTIFS('Chart Database'!$B$6:$B$4005,$A6,'Chart Database'!$D$6:$D$4005,"Advanced",'Chart Database'!$F$6:$F$4005,"Active") | K6: =COUNTIFS('Chart Database'!$B$6:$B$4005,$A6,'Chart Database'!$O$6:$O$4005,"No",'Chart Database'!$F$6:$F$4005,"Active") | L6: =COUNTIFS('Chart Database'!$B$6:$B$4005,$A6,'Chart Database'!$H$6:$H$4005,">="&TODAY()-30,'Chart Database'!$H$6:$H$4005,"<="&TODAY()) | M6: =COUNTIFS('Chart Database'!$B$6:$B$4005,$A6,'Chart Database'!$Q$6:$Q$4005,0,'Chart Database'!$F$6:$F$4005,"Active") | N6: =IF(D6=0,"Nothing in the pool yet",IF(D6>=C6,"At target",IF(K6>0,K6&" chart(s) cannot be graded",IF(D6/C6<0.5,"Under half built","Building"))))
A7: ED Profee | B7: EDP | C7: 400 | D7: =COUNTIFS('Chart Database'!$B$6:$B$4005,$A7,'Chart Database'!$F$6:$F$4005,"Active") | E7: =COUNTIFS('Chart Database'!$B$6:$B$4005,$A7,'Chart Database'!$F$6:$F$4005,"Retired") | F7: =COUNTIF('Chart Database'!$B$6:$B$4005,$A7) | G7: =IF($C7=0,"NA",D7/$C7) | H7: =COUNTIFS('Chart Database'!$B$6:$B$4005,$A7,'Chart Database'!$D$6:$D$4005,"Beginner",'Chart Database'!$F$6:$F$4005,"Active") | I7: =COUNTIFS('Chart Database'!$B$6:$B$4005,$A7,'Chart Database'!$D$6:$D$4005,"Intermediate",'Chart Database'!$F$6:$F$4005,"Active") | J7: =COUNTIFS('Chart Database'!$B$6:$B$4005,$A7,'Chart Database'!$D$6:$D$4005,"Advanced",'Chart Database'!$F$6:$F$4005,"Active") | K7: =COUNTIFS('Chart Database'!$B$6:$B$4005,$A7,'Chart Database'!$O$6:$O$4005,"No",'Chart Database'!$F$6:$F$4005,"Active") | L7: =COUNTIFS('Chart Database'!$B$6:$B$4005,$A7,'Chart Database'!$H$6:$H$4005,">="&TODAY()-30,'Chart Database'!$H$6:$H$4005,"<="&TODAY()) | M7: =COUNTIFS('Chart Database'!$B$6:$B$4005,$A7,'Chart Database'!$Q$6:$Q$4005,0,'Chart Database'!$F$6:$F$4005,"Active") | N7: =IF(D7=0,"Nothing in the pool yet",IF(D7>=C7,"At target",IF(K7>0,K7&" chart(s) cannot be graded",IF(D7/C7<0.5,"Under half built","Building"))))
A8: E/M | B8: EM | C8: 413 | D8: =COUNTIFS('Chart Database'!$B$6:$B$4005,$A8,'Chart Database'!$F$6:$F$4005,"Active") | E8: =COUNTIFS('Chart Database'!$B$6:$B$4005,$A8,'Chart Database'!$F$6:$F$4005,"Retired") | F8: =COUNTIF('Chart Database'!$B$6:$B$4005,$A8) | G8: =IF($C8=0,"NA",D8/$C8) | H8: =COUNTIFS('Chart Database'!$B$6:$B$4005,$A8,'Chart Database'!$D$6:$D$4005,"Beginner",'Chart Database'!$F$6:$F$4005,"Active") | I8: =COUNTIFS('Chart Database'!$B$6:$B$4005,$A8,'Chart Database'!$D$6:$D$4005,"Intermediate",'Chart Database'!$F$6:$F$4005,"Active") | J8: =COUNTIFS('Chart Database'!$B$6:$B$4005,$A8,'Chart Database'!$D$6:$D$4005,"Advanced",'Chart Database'!$F$6:$F$4005,"Active") | K8: =COUNTIFS('Chart Database'!$B$6:$B$4005,$A8,'Chart Database'!$O$6:$O$4005,"No",'Chart Database'!$F$6:$F$4005,"Active") | L8: =COUNTIFS('Chart Database'!$B$6:$B$4005,$A8,'Chart Database'!$H$6:$H$4005,">="&TODAY()-30,'Chart Database'!$H$6:$H$4005,"<="&TODAY()) | M8: =COUNTIFS('Chart Database'!$B$6:$B$4005,$A8,'Chart Database'!$Q$6:$Q$4005,0,'Chart Database'!$F$6:$F$4005,"Active") | N8: =IF(D8=0,"Nothing in the pool yet",IF(D8>=C8,"At target",IF(K8>0,K8&" chart(s) cannot be graded",IF(D8/C8<0.5,"Under half built","Building"))))
A9: SDS | B9: SDS | C9: 132 | D9: =COUNTIFS('Chart Database'!$B$6:$B$4005,$A9,'Chart Database'!$F$6:$F$4005,"Active") | E9: =COUNTIFS('Chart Database'!$B$6:$B$4005,$A9,'Chart Database'!$F$6:$F$4005,"Retired") | F9: =COUNTIF('Chart Database'!$B$6:$B$4005,$A9) | G9: =IF($C9=0,"NA",D9/$C9) | H9: =COUNTIFS('Chart Database'!$B$6:$B$4005,$A9,'Chart Database'!$D$6:$D$4005,"Beginner",'Chart Database'!$F$6:$F$4005,"Active") | I9: =COUNTIFS('Chart Database'!$B$6:$B$4005,$A9,'Chart Database'!$D$6:$D$4005,"Intermediate",'Chart Database'!$F$6:$F$4005,"Active") | J9: =COUNTIFS('Chart Database'!$B$6:$B$4005,$A9,'Chart Database'!$D$6:$D$4005,"Advanced",'Chart Database'!$F$6:$F$4005,"Active") | K9: =COUNTIFS('Chart Database'!$B$6:$B$4005,$A9,'Chart Database'!$O$6:$O$4005,"No",'Chart Database'!$F$6:$F$4005,"Active") | L9: =COUNTIFS('Chart Database'!$B$6:$B$4005,$A9,'Chart Database'!$H$6:$H$4005,">="&TODAY()-30,'Chart Database'!$H$6:$H$4005,"<="&TODAY()) | M9: =COUNTIFS('Chart Database'!$B$6:$B$4005,$A9,'Chart Database'!$Q$6:$Q$4005,0,'Chart Database'!$F$6:$F$4005,"Active") | N9: =IF(D9=0,"Nothing in the pool yet",IF(D9>=C9,"At target",IF(K9>0,K9&" chart(s) cannot be graded",IF(D9/C9<0.5,"Under half built","Building"))))
A10: Surgery | B10: SURG | C10: 300 | D10: =COUNTIFS('Chart Database'!$B$6:$B$4005,$A10,'Chart Database'!$F$6:$F$4005,"Active") | E10: =COUNTIFS('Chart Database'!$B$6:$B$4005,$A10,'Chart Database'!$F$6:$F$4005,"Retired") | F10: =COUNTIF('Chart Database'!$B$6:$B$4005,$A10) | G10: =IF($C10=0,"NA",D10/$C10) | H10: =COUNTIFS('Chart Database'!$B$6:$B$4005,$A10,'Chart Database'!$D$6:$D$4005,"Beginner",'Chart Database'!$F$6:$F$4005,"Active") | I10: =COUNTIFS('Chart Database'!$B$6:$B$4005,$A10,'Chart Database'!$D$6:$D$4005,"Intermediate",'Chart Database'!$F$6:$F$4005,"Active") | J10: =COUNTIFS('Chart Database'!$B$6:$B$4005,$A10,'Chart Database'!$D$6:$D$4005,"Advanced",'Chart Database'!$F$6:$F$4005,"Active") | K10: =COUNTIFS('Chart Database'!$B$6:$B$4005,$A10,'Chart Database'!$O$6:$O$4005,"No",'Chart Database'!$F$6:$F$4005,"Active") | L10: =COUNTIFS('Chart Database'!$B$6:$B$4005,$A10,'Chart Database'!$H$6:$H$4005,">="&TODAY()-30,'Chart Database'!$H$6:$H$4005,"<="&TODAY()) | M10: =COUNTIFS('Chart Database'!$B$6:$B$4005,$A10,'Chart Database'!$Q$6:$Q$4005,0,'Chart Database'!$F$6:$F$4005,"Active") | N10: =IF(D10=0,"Nothing in the pool yet",IF(D10>=C10,"At target",IF(K10>0,K10&" chart(s) cannot be graded",IF(D10/C10<0.5,"Under half built","Building"))))
A11: ED Single Path | B11: EDSP | C11: 300 | D11: =COUNTIFS('Chart Database'!$B$6:$B$4005,$A11,'Chart Database'!$F$6:$F$4005,"Active") | E11: =COUNTIFS('Chart Database'!$B$6:$B$4005,$A11,'Chart Database'!$F$6:$F$4005,"Retired") | F11: =COUNTIF('Chart Database'!$B$6:$B$4005,$A11) | G11: =IF($C11=0,"NA",D11/$C11) | H11: =COUNTIFS('Chart Database'!$B$6:$B$4005,$A11,'Chart Database'!$D$6:$D$4005,"Beginner",'Chart Database'!$F$6:$F$4005,"Active") | I11: =COUNTIFS('Chart Database'!$B$6:$B$4005,$A11,'Chart Database'!$D$6:$D$4005,"Intermediate",'Chart Database'!$F$6:$F$4005,"Active") | J11: =COUNTIFS('Chart Database'!$B$6:$B$4005,$A11,'Chart Database'!$D$6:$D$4005,"Advanced",'Chart Database'!$F$6:$F$4005,"Active") | K11: =COUNTIFS('Chart Database'!$B$6:$B$4005,$A11,'Chart Database'!$O$6:$O$4005,"No",'Chart Database'!$F$6:$F$4005,"Active") | L11: =COUNTIFS('Chart Database'!$B$6:$B$4005,$A11,'Chart Database'!$H$6:$H$4005,">="&TODAY()-30,'Chart Database'!$H$6:$H$4005,"<="&TODAY()) | M11: =COUNTIFS('Chart Database'!$B$6:$B$4005,$A11,'Chart Database'!$Q$6:$Q$4005,0,'Chart Database'!$F$6:$F$4005,"Active") | N11: =IF(D11=0,"Nothing in the pool yet",IF(D11>=C11,"At target",IF(K11>0,K11&" chart(s) cannot be graded",IF(D11/C11<0.5,"Under half built","Building"))))
A12: TOTAL | C12: =SUM(C5:C11) | D12: =SUM(D5:D11) | E12: =SUM(E5:E11) | F12: =SUM(F5:F11) | G12: =IF(C12=0,"NA",D12/C12) | H12: =SUM(H5:H11) | I12: =SUM(I5:I11) | J12: =SUM(J5:J11) | K12: =SUM(K5:K11) | L12: =SUM(L5:L11) | M12: =SUM(M5:M11)
A14: This sheet counts CHARTS. The Category Dictionary counts TOPIC COVERAGE, and its total is larger because a chart carrying "Sepsis, AKI" is counted under both topics. Neither is wrong; they answer different questions.
A15: Difficulty uses the application's own values — Beginner, Intermediate, Advanced. The composition taxonomy speaks of Basic, Moderate and Complex tiers; the Field Conventions sheet maps the two.

Sheet Monthly Trend
A1: Monthly Trend — uploads by month
A2: Counted from created_at. Change the start month and the whole table moves with it.
A4: FIRST MONTH SHOWN
A5: Start month | B5: 45931 | D5: 24 months are shown from here. Any month with no uploads reads 0 rather than being skipped, so a gap in sourcing is visible.
A7: Month | B7: IP-DRG | C7: ED Facility | D7: ED Profee | E7: E/M | F7: SDS | G7: Surgery | H7: ED Single Path | I7: Total | J7: Cumulative | K7: Reading
A8: =$B$5 | B8: =COUNTIFS('Chart Database'!$B$6:$B$4005,"IP-DRG",'Chart Database'!$H$6:$H$4005,">="&$A8,'Chart Database'!$H$6:$H$4005,"<"&EDATE($A8,1)) | C8: =COUNTIFS('Chart Database'!$B$6:$B$4005,"ED Facility",'Chart Database'!$H$6:$H$4005,">="&$A8,'Chart Database'!$H$6:$H$4005,"<"&EDATE($A8,1)) | D8: =COUNTIFS('Chart Database'!$B$6:$B$4005,"ED Profee",'Chart Database'!$H$6:$H$4005,">="&$A8,'Chart Database'!$H$6:$H$4005,"<"&EDATE($A8,1)) | E8: =COUNTIFS('Chart Database'!$B$6:$B$4005,"E/M",'Chart Database'!$H$6:$H$4005,">="&$A8,'Chart Database'!$H$6:$H$4005,"<"&EDATE($A8,1)) | F8: =COUNTIFS('Chart Database'!$B$6:$B$4005,"SDS",'Chart Database'!$H$6:$H$4005,">="&$A8,'Chart Database'!$H$6:$H$4005,"<"&EDATE($A8,1)) | G8: =COUNTIFS('Chart Database'!$B$6:$B$4005,"Surgery",'Chart Database'!$H$6:$H$4005,">="&$A8,'Chart Database'!$H$6:$H$4005,"<"&EDATE($A8,1)) | H8: =COUNTIFS('Chart Database'!$B$6:$B$4005,"ED Single Path",'Chart Database'!$H$6:$H$4005,">="&$A8,'Chart Database'!$H$6:$H$4005,"<"&EDATE($A8,1)) | I8: =SUM(B8:H8) | J8: =SUM($I$8:I8) | K8: =IF(I8=0,"no uploads this month","")
A9: =EDATE($B$5,1) | B9: =COUNTIFS('Chart Database'!$B$6:$B$4005,"IP-DRG",'Chart Database'!$H$6:$H$4005,">="&$A9,'Chart Database'!$H$6:$H$4005,"<"&EDATE($A9,1)) | C9: =COUNTIFS('Chart Database'!$B$6:$B$4005,"ED Facility",'Chart Database'!$H$6:$H$4005,">="&$A9,'Chart Database'!$H$6:$H$4005,"<"&EDATE($A9,1)) | D9: =COUNTIFS('Chart Database'!$B$6:$B$4005,"ED Profee",'Chart Database'!$H$6:$H$4005,">="&$A9,'Chart Database'!$H$6:$H$4005,"<"&EDATE($A9,1)) | E9: =COUNTIFS('Chart Database'!$B$6:$B$4005,"E/M",'Chart Database'!$H$6:$H$4005,">="&$A9,'Chart Database'!$H$6:$H$4005,"<"&EDATE($A9,1)) | F9: =COUNTIFS('Chart Database'!$B$6:$B$4005,"SDS",'Chart Database'!$H$6:$H$4005,">="&$A9,'Chart Database'!$H$6:$H$4005,"<"&EDATE($A9,1)) | G9: =COUNTIFS('Chart Database'!$B$6:$B$4005,"Surgery",'Chart Database'!$H$6:$H$4005,">="&$A9,'Chart Database'!$H$6:$H$4005,"<"&EDATE($A9,1)) | H9: =COUNTIFS('Chart Database'!$B$6:$B$4005,"ED Single Path",'Chart Database'!$H$6:$H$4005,">="&$A9,'Chart Database'!$H$6:$H$4005,"<"&EDATE($A9,1)) | I9: =SUM(B9:H9) | J9: =SUM($I$8:I9) | K9: =IF(I9=0,"no uploads this month","")
A10: =EDATE($B$5,2) | B10: =COUNTIFS('Chart Database'!$B$6:$B$4005,"IP-DRG",'Chart Database'!$H$6:$H$4005,">="&$A10,'Chart Database'!$H$6:$H$4005,"<"&EDATE($A10,1)) | C10: =COUNTIFS('Chart Database'!$B$6:$B$4005,"ED Facility",'Chart Database'!$H$6:$H$4005,">="&$A10,'Chart Database'!$H$6:$H$4005,"<"&EDATE($A10,1)) | D10: =COUNTIFS('Chart Database'!$B$6:$B$4005,"ED Profee",'Chart Database'!$H$6:$H$4005,">="&$A10,'Chart Database'!$H$6:$H$4005,"<"&EDATE($A10,1)) | E10: =COUNTIFS('Chart Database'!$B$6:$B$4005,"E/M",'Chart Database'!$H$6:$H$4005,">="&$A10,'Chart Database'!$H$6:$H$4005,"<"&EDATE($A10,1)) | F10: =COUNTIFS('Chart Database'!$B$6:$B$4005,"SDS",'Chart Database'!$H$6:$H$4005,">="&$A10,'Chart Database'!$H$6:$H$4005,"<"&EDATE($A10,1)) | G10: =COUNTIFS('Chart Database'!$B$6:$B$4005,"Surgery",'Chart Database'!$H$6:$H$4005,">="&$A10,'Chart Database'!$H$6:$H$4005,"<"&EDATE($A10,1)) | H10: =COUNTIFS('Chart Database'!$B$6:$B$4005,"ED Single Path",'Chart Database'!$H$6:$H$4005,">="&$A10,'Chart Database'!$H$6:$H$4005,"<"&EDATE($A10,1)) | I10: =SUM(B10:H10) | J10: =SUM($I$8:I10) | K10: =IF(I10=0,"no uploads this month","")
A11: =EDATE($B$5,3) | B11: =COUNTIFS('Chart Database'!$B$6:$B$4005,"IP-DRG",'Chart Database'!$H$6:$H$4005,">="&$A11,'Chart Database'!$H$6:$H$4005,"<"&EDATE($A11,1)) | C11: =COUNTIFS('Chart Database'!$B$6:$B$4005,"ED Facility",'Chart Database'!$H$6:$H$4005,">="&$A11,'Chart Database'!$H$6:$H$4005,"<"&EDATE($A11,1)) | D11: =COUNTIFS('Chart Database'!$B$6:$B$4005,"ED Profee",'Chart Database'!$H$6:$H$4005,">="&$A11,'Chart Database'!$H$6:$H$4005,"<"&EDATE($A11,1)) | E11: =COUNTIFS('Chart Database'!$B$6:$B$4005,"E/M",'Chart Database'!$H$6:$H$4005,">="&$A11,'Chart Database'!$H$6:$H$4005,"<"&EDATE($A11,1)) | F11: =COUNTIFS('Chart Database'!$B$6:$B$4005,"SDS",'Chart Database'!$H$6:$H$4005,">="&$A11,'Chart Database'!$H$6:$H$4005,"<"&EDATE($A11,1)) | G11: =COUNTIFS('Chart Database'!$B$6:$B$4005,"Surgery",'Chart Database'!$H$6:$H$4005,">="&$A11,'Chart Database'!$H$6:$H$4005,"<"&EDATE($A11,1)) | H11: =COUNTIFS('Chart Database'!$B$6:$B$4005,"ED Single Path",'Chart Database'!$H$6:$H$4005,">="&$A11,'Chart Database'!$H$6:$H$4005,"<"&EDATE($A11,1)) | I11: =SUM(B11:H11) | J11: =SUM($I$8:I11) | K11: =IF(I11=0,"no uploads this month","")
