Workbook

Sheet Read Me
A1: PracticeLab Chart Inventory Tracker
A2: End-to-end tracking for every chart, from candidate to retirement · built 15 October 2026
B5: What this is
B6: The operational companion to PracticeLab_Chart_Composition_Taxonomy.xlsx. That workbook is the standard: what the pool should contain, topic by topic. This one is the record: what it actually contains, who is building it, and how far behind the build is.
B7: The register starts empty on purpose. A row exists once a chart exists, so nothing in this file is a placeholder somebody has to maintain. What is not yet sourced is a number on the dashboard, computed against the plan — not two thousand blank rows.
B9: The sheets, in the order you need them
B10: Dashboard | C10: Read-only. Fourteen figures, a stage funnel and the difficulty mix, all formulas. Start here, then follow whatever is red.
B11: Chart Register | C11: Where the work is recorded. One row per chart, five dated stages, dropdowns on every classified field. The only sheet most people type into.
B12: Topic Plan | C12: All 103 topics with their targets, and live counts beside them. This is where a coverage gap shows up at the level sourcing actually works at.
B13: Specialty View | C13: The same thing one level up: progress, slippage and status per specialty. The view for a weekly update.
B14: Schedule Model | C14: Where every expected date comes from. Two editable columns — build hours per chart and FTE assigned — drive the whole schedule.
B15: Issues Log | C15: Anything blocking a chart or casting doubt on one already live. Severity, owner, target resolution date, overdue flag.
B16: Refresh & Retirement | C16: Sizes the next half-yearly refresh and flags charts past the usage or age limit.
B17: Lists | C17: The source of every dropdown. Add a value here, never straight into a cell.
B19: The five stages
B20: Identified, De-identified, Built, Validated, Live — then Retired, or On hold while an issue runs. Each has its own date column, which is what makes the stage funnel on the dashboard meaningful: a stage holding more charts than the ones after it is the bottleneck, and the Days in stage column names the individual charts stuck there.
B21: Set the Status column to where a chart is now, and fill the date column for each stage as it is reached. The two are not the same field and both are needed: the status drives every count, the dates drive the ageing.
B23: How a delay is measured
B24: Where expected dates come from | C24: The Schedule Model multiplies a specialty's target by its build hours per chart, divides by the hours one FTE has in a week, and lays the result out from the programme start date. Topics within a specialty are sequenced by build priority, so the P1 topics carry the earliest dates.
B25: What a slipping date means | C25: Either the build rate is wrong or the staffing is. Both are editable columns on that sheet, so a date that cannot be met should be met by changing the assumption on the record rather than by quietly missing it.
B26: Per chart | C26: Days late on the register compares the expected live date with today, or with the actual live date once the chart is live. Positive means late.
B27: Per topic and specialty | C27: Days vs expected compares today with the modelled completion date, and reads On target as soon as live reaches target.
B29: What this file cannot do
B30: It has no native PivotTables — the tool that writes it cannot create them. The summary views are formulas instead, which need no refresh and survive being emailed. If you want ad-hoc pivoting, select the register and insert a PivotTable; it is a flat table with a header row, which is all a pivot needs.
B31: Formulas cover register rows 5 to 1004 and issue rows 5 to 504. That is headroom for a pool of 2,942 across several refresh cycles, but it is not infinite: paste past the end and the dashboard will quietly stop counting the overflow. Extend the formulas, do not type past them.
B32: Nothing here is connected to the platform. It is a planning and governance record maintained by hand, and the moment Topic ID exists as a field on the chart record in the application, the counts in it should come from there instead.
B34: Rules worth keeping
B35: A suspected answer-key problem puts the chart On hold, not Live-with-a-note. A wrong key silently grades everyone against it, which is worse than a missing chart.
B36: Retiring a chart keeps its row. Deleting the row loses the history that lets the dashboard say what left the pool and when.
B37: Every rate on the dashboard carries its denominator in the description beside it. Pool complete is live over planned; the difficulty mix is over live charts only, because that is the pool a coder actually meets.
B38: A topic with no target reads NA, not 0%. They are different statements: one means no target was set, the other means nothing was built against one.
B40: What the colours mean
B41: Green | C41: Done or healthy: live, complete, on track, a closed issue.
B42: Blue | C42: In flight: a chart moving through the stages, or a topic at or above the gap threshold.
B43: Amber | C43: Watch it: on hold, stalled over 30 days, a coverage gap, a P1 topic, more charts qualifying to retire than policy removes.
B44: Red | C44: Act now: past the expected date, below the gap threshold, a blocker, an overdue issue, an unrecognised Topic ID.
B45: Cream | C45: You type here. Build hours, FTE, the start date, the retirement limits.
B46: Grey-blue | C46: Computed — do not type. These columns fill themselves from the Topic ID or the dates.
B48: Colour is never the only signal: every highlighted cell also carries the words, so the workbook still reads correctly printed in black and white or to anyone who cannot distinguish the hues.

Sheet Dashboard
A1: PracticeLab chart inventory — dashboard
A2: Everything here is a formula over the register, the plan and the issues log. Nothing is typed. Built 15 October 2026; the figures are live whenever the file is opened.
A5: Planned charts | B5: ='Topic Plan'!$H$116 | C5: Sum of every topic target. The size of the finished pool.
A6: Live in the pool | B6: =COUNTIF('Chart Register'!$N$5:$N$1004,"Live") | C6: Charts available to a batch right now.
A7: Pool complete | B7: =IF(B5=0,"NA",B6/B5) | C7: Live as a share of planned. Reads NA before any target exists.
A8: In build | B8: =COUNTIF('Chart Register'!$N$5:$N$1004,"Identified")+COUNTIF('Chart Register'!$N$5:$N$1004,"De-identified")+COUNTIF('Chart Register'!$N$5:$N$1004,"Built")+COUNTIF('Chart Register'!$N$5:$N$1004,"Validated") | C8: Logged and moving: identified, de-identified, built or validated, but not yet live.
A9: Not yet sourced | B9: =MAX(0,B5-COUNTIF('Chart Register'!$A$5:$A$1004,"<>")) | C9: Planned charts with no register row at all. The sourcing backlog.
A10: Added live, last 30 days | B10: =COUNTIFS('Chart Register'!$S$5:$S$1004,">="&TODAY()-30,'Chart Register'!$S$5:$S$1004,"<="&TODAY()) | C10: Charts that went live in the last month. The build rate, measured rather than assumed.
A11: Retired, last 90 days | B11: =COUNTIFS('Chart Register'!$T$5:$T$1004,">="&TODAY()-90,'Chart Register'!$T$5:$T$1004,"<="&TODAY()) | C11: Recent retirements. HC policy retires 10% of the pool each half-yearly refresh.
A12: On hold | B12: =COUNTIF('Chart Register'!$N$5:$N$1004,"On hold") | C12: Charts stopped by an unresolved issue. These are not in the pool and are not progressing.
A13: Topics below threshold | B13: =COUNTIF('Topic Plan'!$P$5:$P$115,"BELOW*") | C13: Topics under the HC section 9 gap threshold. Each one triggers targeted sourcing.
A14: Charts past expected date | B14: =COUNTIF('Chart Register'!$V$5:$V$1004,">0") | C14: Logged charts whose expected live date has passed and which are not live.
A15: Stalled over 30 days | B15: =COUNTIF('Chart Register'!$W$5:$W$1004,">30") | C15: Charts sitting in the same stage for over a month. Where the build is actually blocked.
A16: Open issues | B16: =COUNTIF('Issues Log'!$K$5:$K$504,"Open")+COUNTIF('Issues Log'!$K$5:$K$504,"In progress") | C16: Unresolved issues across every specialty.
A17: Blocker issues open | B17: =COUNTIFS('Issues Log'!$G$5:$G$504,"Blocker",'Issues Log'!$K$5:$K$504,"Open")+COUNTIFS('Issues Log'!$G$5:$G$504,"Blocker",'Issues Log'!$K$5:$K$504,"In progress") | C17: Issues stopping a chart outright. Clear these first.
A18: Issues overdue | B18: =COUNTIF('Issues Log'!$O$5:$O$504,"OVERDUE") | C18: Open issues past their own target resolution date.
A20: STAGE FUNNEL — WHERE THE CHARTS ARE
A21: Stage | B21: Charts | C21: % of planned | J21: Reading
A22: Identified | B22: =COUNTIF('Chart Register'!$N$5:$N$1004,"Identified") | C22: =IF($B$5=0,"NA",B22/$B$5) | J22: A stage holding far more charts than the ones after it is the bottleneck. Validated piling up means second-level review is the constraint, not sourcing.
A23: De-identified | B23: =COUNTIF('Chart Register'!$N$5:$N$1004,"De-identified") | C23: =IF($B$5=0,"NA",B23/$B$5)
A24: Built | B24: =COUNTIF('Chart Register'!$N$5:$N$1004,"Built") | C24: =IF($B$5=0,"NA",B24/$B$5)
A25: Validated | B25: =COUNTIF('Chart Register'!$N$5:$N$1004,"Validated") | C25: =IF($B$5=0,"NA",B25/$B$5)
A26: Live | B26: =COUNTIF('Chart Register'!$N$5:$N$1004,"Live") | C26: =IF($B$5=0,"NA",B26/$B$5)
A27: On hold | B27: =COUNTIF('Chart Register'!$N$5:$N$1004,"On hold") | C27: =IF($B$5=0,"NA",B27/$B$5)
A28: Retired | B28: =COUNTIF('Chart Register'!$N$5:$N$1004,"Retired") | C28: =IF($B$5=0,"NA",B28/$B$5)
A30: DIFFICULTY MIX — ACTUAL AGAINST THE HC 40 / 40 / 20 TARGET
A31: Tier | B31: Live charts | C31: Actual % | D31: Target % | E31: Deviation | J31: Reading
A32: Basic | B32: =COUNTIFS('Chart Register'!$G$5:$G$1004,"Basic",'Chart Register'!$N$5:$N$1004,"Live") | C32: =IF($B$6=0,"NA",B32/$B$6) | D32: 0.4 | E32: =IF($B$6=0,"NA",C32-D32) | J32: Measured over live charts only, so it reports the pool a coder actually meets. A pool drifting toward Basic teaches less than the mix intends; one drifting Complex fails Week 1.
A33: Moderate | B33: =COUNTIFS('Chart Register'!$G$5:$G$1004,"Moderate",'Chart Register'!$N$5:$N$1004,"Live") | C33: =IF($B$6=0,"NA",B33/$B$6) | D33: 0.4 | E33: =IF($B$6=0,"NA",C33-D33)
A34: Complex | B34: =COUNTIFS('Chart Register'!$G$5:$G$1004,"Complex",'Chart Register'!$N$5:$N$1004,"Live") | C34: =IF($B$6=0,"NA",B34/$B$6) | D34: 0.2 | E34: =IF($B$6=0,"NA",C34-D34)
A36: Native Excel PivotTables cannot be generated by the tool that writes this file, so the summary views here and on Specialty View are formula-driven instead. They need no refresh and survive being emailed. For ad-hoc pivoting, select the register range and insert a PivotTable — the register is a flat table with a header row, which is all a pivot needs.
A37: Every count here reads register rows 5 to 1004 and issue rows 5 to 504. Paste beyond those rows and the dashboard will quietly stop counting the overflow, so extend the formulas rather than typing past the end.

Sheet Chart Register
A1: Chart Register — one row per chart
A2: Starts empty: a row exists once a chart exists. Grey columns fill themselves from the Topic ID — do not type into them.
A4: Chart ID | B4: Specialty | C4: Topic ID | D4: Topic (auto) | E4: Coverage category (auto) | F4: Priority (auto) | G4: Difficulty tier | H4: Source type | I4: Client / facility ref | J4: Primary channel | K4: Learning objective | L4: Code-set version | M4: Owner | N4: Status | O4: Date identified | P4: Date de-identified | Q4: Date built | R4: Date validated | S4: Date live | T4: Date retired | U4: Expected live date | V4: Days late (auto) | W4: Days in stage (auto) | X4: Batches used | Y4: Open issues (auto) | Z4: Notes
D5: =IF($C5="","",IFERROR(INDEX('Topic Plan'!$C$5:$C$115,MATCH($C5,'Topic Plan'!$B$5:$B$115,0)),"UNKNOWN TOPIC ID")) | E5: =IF($C5="","",IFERROR(INDEX('Topic Plan'!$D$5:$D$115,MATCH($C5,'Topic Plan'!$B$5:$B$115,0)),"")) | F5: =IF($C5="","",IFERROR(INDEX('Topic Plan'!$E$5:$E$115,MATCH($C5,'Topic Plan'!$B$5:$B$115,0)),"")) | V5: =IF(OR($A5="",$U5=""),"",IF($S5<>"",MAX(0,$S5-$U5),MAX(0,TODAY()-$U5))) | W5: =IF($A5="","",IF(OR($N5="Live",$N5="Retired"),"",TODAY()-MAX($O5,$P5,$Q5,$R5))) | Y5: =IF($A5="","",COUNTIFS('Issues Log'!$C$5:$C$504,$A5,'Issues Log'!$K$5:$K$504,"Open")+COUNTIFS('Issues Log'!$C$5:$C$504,$A5,'Issues Log'!$K$5:$K$504,"In progress"))
D6: =IF($C6="","",IFERROR(INDEX('Topic Plan'!$C$5:$C$115,MATCH($C6,'Topic Plan'!$B$5:$B$115,0)),"UNKNOWN TOPIC ID")) | E6: =IF($C6="","",IFERROR(INDEX('Topic Plan'!$D$5:$D$115,MATCH($C6,'Topic Plan'!$B$5:$B$115,0)),"")) | F6: =IF($C6="","",IFERROR(INDEX('Topic Plan'!$E$5:$E$115,MATCH($C6,'Topic Plan'!$B$5:$B$115,0)),"")) | V6: =IF(OR($A6="",$U6=""),"",IF($S6<>"",MAX(0,$S6-$U6),MAX(0,TODAY()-$U6))) | W6: =IF($A6="","",IF(OR($N6="Live",$N6="Retired"),"",TODAY()-MAX($O6,$P6,$Q6,$R6))) | Y6: =IF($A6="","",COUNTIFS('Issues Log'!$C$5:$C$504,$A6,'Issues Log'!$K$5:$K$504,"Open")+COUNTIFS('Issues Log'!$C$5:$C$504,$A6,'Issues Log'!$K$5:$K$504,"In progress"))
D7: =IF($C7="","",IFERROR(INDEX('Topic Plan'!$C$5:$C$115,MATCH($C7,'Topic Plan'!$B$5:$B$115,0)),"UNKNOWN TOPIC ID")) | E7: =IF($C7="","",IFERROR(INDEX('Topic Plan'!$D$5:$D$115,MATCH($C7,'Topic Plan'!$B$5:$B$115,0)),"")) | F7: =IF($C7="","",IFERROR(INDEX('Topic Plan'!$E$5:$E$115,MATCH($C7,'Topic Plan'!$B$5:$B$115,0)),"")) | V7: =IF(OR($A7="",$U7=""),"",IF($S7<>"",MAX(0,$S7-$U7),MAX(0,TODAY()-$U7))) | W7: =IF($A7="","",IF(OR($N7="Live",$N7="Retired"),"",TODAY()-MAX($O7,$P7,$Q7,$R7))) | Y7: =IF($A7="","",COUNTIFS('Issues Log'!$C$5:$C$504,$A7,'Issues Log'!$K$5:$K$504,"Open")+COUNTIFS('Issues Log'!$C$5:$C$504,$A7,'Issues Log'!$K$5:$K$504,"In progress"))
D8: =IF($C8="","",IFERROR(INDEX('Topic Plan'!$C$5:$C$115,MATCH($C8,'Topic Plan'!$B$5:$B$115,0)),"UNKNOWN TOPIC ID")) | E8: =IF($C8="","",IFERROR(INDEX('Topic Plan'!$D$5:$D$115,MATCH($C8,'Topic Plan'!$B$5:$B$115,0)),"")) | F8: =IF($C8="","",IFERROR(INDEX('Topic Plan'!$E$5:$E$115,MATCH($C8,'Topic Plan'!$B$5:$B$115,0)),"")) | V8: =IF(OR($A8="",$U8=""),"",IF($S8<>"",MAX(0,$S8-$U8),MAX(0,TODAY()-$U8))) | W8: =IF($A8="","",IF(OR($N8="Live",$N8="Retired"),"",TODAY()-MAX($O8,$P8,$Q8,$R8))) | Y8: =IF($A8="","",COUNTIFS('Issues Log'!$C$5:$C$504,$A8,'Issues Log'!$K$5:$K$504,"Open")+COUNTIFS('Issues Log'!$C$5:$C$504,$A8,'Issues Log'!$K$5:$K$504,"In progress"))
D9: =IF($C9="","",IFERROR(INDEX('Topic Plan'!$C$5:$C$115,MATCH($C9,'Topic Plan'!$B$5:$B$115,0)),"UNKNOWN TOPIC ID")) | E9: =IF($C9="","",IFERROR(INDEX('Topic Plan'!$D$5:$D$115,MATCH($C9,'Topic Plan'!$B$5:$B$115,0)),"")) | F9: =IF($C9="","",IFERROR(INDEX('Topic Plan'!$E$5:$E$115,MATCH($C9,'Topic Plan'!$B$5:$B$115,0)),"")) | V9: =IF(OR($A9="",$U9=""),"",IF($S9<>"",MAX(0,$S9-$U9),MAX(0,TODAY()-$U9))) | W9: =IF($A9="","",IF(OR($N9="Live",$N9="Retired"),"",TODAY()-MAX($O9,$P9,$Q9,$R9))) | Y9: =IF($A9="","",COUNTIFS('Issues Log'!$C$5:$C$504,$A9,'Issues Log'!$K$5:$K$504,"Open")+COUNTIFS('Issues Log'!$C$5:$C$504,$A9,'Issues Log'!$K$5:$K$504,"In progress"))
D10: =IF($C10="","",IFERROR(INDEX('Topic Plan'!$C$5:$C$115,MATCH($C10,'Topic Plan'!$B$5:$B$115,0)),"UNKNOWN TOPIC ID")) | E10: =IF($C10="","",IFERROR(INDEX('Topic Plan'!$D$5:$D$115,MATCH($C10,'Topic Plan'!$B$5:$B$115,0)),"")) | F10: =IF($C10="","",IFERROR(INDEX('Topic Plan'!$E$5:$E$115,MATCH($C10,'Topic Plan'!$B$5:$B$115,0)),"")) | V10: =IF(OR($A10="",$U10=""),"",IF($S10<>"",MAX(0,$S10-$U10),MAX(0,TODAY()-$U10))) | W10: =IF($A10="","",IF(OR($N10="Live",$N10="Retired"),"",TODAY()-MAX($O10,$P10,$Q10,$R10))) | Y10: =IF($A10="","",COUNTIFS('Issues Log'!$C$5:$C$504,$A10,'Issues Log'!$K$5:$K$504,"Open")+COUNTIFS('Issues Log'!$C$5:$C$504,$A10,'Issues Log'!$K$5:$K$504,"In progress"))
D11: =IF($C11="","",IFERROR(INDEX('Topic Plan'!$C$5:$C$115,MATCH($C11,'Topic Plan'!$B$5:$B$115,0)),"UNKNOWN TOPIC ID")) | E11: =IF($C11="","",IFERROR(INDEX('Topic Plan'!$D$5:$D$115,MATCH($C11,'Topic Plan'!$B$5:$B$115,0)),"")) | F11: =IF($C11="","",IFERROR(INDEX('Topic Plan'!$E$5:$E$115,MATCH($C11,'Topic Plan'!$B$5:$B$115,0)),"")) | V11: =IF(OR($A11="",$U11=""),"",IF($S11<>"",MAX(0,$S11-$U11),MAX(0,TODAY()-$U11))) | W11: =IF($A11="","",IF(OR($N11="Live",$N11="Retired"),"",TODAY()-MAX($O11,$P11,$Q11,$R11))) | Y11: =IF($A11="","",COUNTIFS('Issues Log'!$C$5:$C$504,$A11,'Issues Log'!$K$5:$K$504,"Open")+COUNTIFS('Issues Log'!$C$5:$C$504,$A11,'Issues Log'!$K$5:$K$504,"In progress"))
D12: =IF($C12="","",IFERROR(INDEX('Topic Plan'!$C$5:$C$115,MATCH($C12,'Topic Plan'!$B$5:$B$115,0)),"UNKNOWN TOPIC ID")) | E12: =IF($C12="","",IFERROR(INDEX('Topic Plan'!$D$5:$D$115,MATCH($C12,'Topic Plan'!$B$5:$B$115,0)),"")) | F12: =IF($C12="","",IFERROR(INDEX('Topic Plan'!$E$5:$E$115,MATCH($C12,'Topic Plan'!$B$5:$B$115,0)),"")) | V12: =IF(OR($A12="",$U12=""),"",IF($S12<>"",MAX(0,$S12-$U12),MAX(0,TODAY()-$U12))) | W12: =IF($A12="","",IF(OR($N12="Live",$N12="Retired"),"",TODAY()-MAX($O12,$P12,$Q12,$R12))) | Y12: =IF($A12="","",COUNTIFS('Issues Log'!$C$5:$C$504,$A12,'Issues Log'!$K$5:$K$504,"Open")+COUNTIFS('Issues Log'!$C$5:$C$504,$A12,'Issues Log'!$K$5:$K$504,"In progress"))
D13: =IF($C13="","",IFERROR(INDEX('Topic Plan'!$C$5:$C$115,MATCH($C13,'Topic Plan'!$B$5:$B$115,0)),"UNKNOWN TOPIC ID")) | E13: =IF($C13="","",IFERROR(INDEX('Topic Plan'!$D$5:$D$115,MATCH($C13,'Topic Plan'!$B$5:$B$115,0)),"")) | F13: =IF($C13="","",IFERROR(INDEX('Topic Plan'!$E$5:$E$115,MATCH($C13,'Topic Plan'!$B$5:$B$115,0)),"")) | V13: =IF(OR($A13="",$U13=""),"",IF($S13<>"",MAX(0,$S13-$U13),MAX(0,TODAY()-$U13))) | W13: =IF($A13="","",IF(OR($N13="Live",$N13="Retired"),"",TODAY()-MAX($O13,$P13,$Q13,$R13))) | Y13: =IF($A13="","",COUNTIFS('Issues Log'!$C$5:$C$504,$A13,'Issues Log'!$K$5:$K$504,"Open")+COUNTIFS('Issues Log'!$C$5:$C$504,$A13,'Issues Log'!$K$5:$K$504,"In progress"))
D14: =IF($C14="","",IFERROR(INDEX('Topic Plan'!$C$5:$C$115,MATCH($C14,'Topic Plan'!$B$5:$B$115,0)),"UNKNOWN TOPIC ID")) | E14: =IF($C14="","",IFERROR(INDEX('Topic Plan'!$D$5:$D$115,MATCH($C14,'Topic Plan'!$B$5:$B$115,0)),"")) | F14: =IF($C14="","",IFERROR(INDEX('Topic Plan'!$E$5:$E$115,MATCH($C14,'Topic Plan'!$B$5:$B$115,0)),"")) | V14: =IF(OR($A14="",$U14=""),"",IF($S14<>"",MAX(0,$S14-$U14),MAX(0,TODAY()-$U14))) | W14: =IF($A14="","",IF(OR($N14="Live",$N14="Retired"),"",TODAY()-MAX($O14,$P14,$Q14,$R14))) | Y14: =IF($A14="","",COUNTIFS('Issues Log'!$C$5:$C$504,$A14,'Issues Log'!$K$5:$K$504,"Open")+COUNTIFS('Issues Log'!$C$5:$C$504,$A14,'Issues Log'!$K$5:$K$504,"In progress"))
D15: =IF($C15="","",IFERROR(INDEX('Topic Plan'!$C$5:$C$115,MATCH($C15,'Topic Plan'!$B$5:$B$115,0)),"UNKNOWN TOPIC ID")) | E15: =IF($C15="","",IFERROR(INDEX('Topic Plan'!$D$5:$D$115,MATCH($C15,'Topic Plan'!$B$5:$B$115,0)),"")) | F15: =IF($C15="","",IFERROR(INDEX('Topic Plan'!$E$5:$E$115,MATCH($C15,'Topic Plan'!$B$5:$B$115,0)),"")) | V15: =IF(OR($A15="",$U15=""),"",IF($S15<>"",MAX(0,$S15-$U15),MAX(0,TODAY()-$U15))) | W15: =IF($A15="","",IF(OR($N15="Live",$N15="Retired"),"",TODAY()-MAX($O15,$P15,$Q15,$R15))) | Y15: =IF($A15="","",COUNTIFS('Issues Log'!$C$5:$C$504,$A15,'Issues Log'!$K$5:$K$504,"Open")+COUNTIFS('Issues Log'!$C$5:$C$504,$A15,'Issues Log'!$K$5:$K$504,"In progress"))
D16: =IF($C16="","",IFERROR(INDEX('Topic Plan'!$C$5:$C$115,MATCH($C16,'Topic Plan'!$B$5:$B$115,0)),"UNKNOWN TOPIC ID")) | E16: =IF($C16="","",IFERROR(INDEX('Topic Plan'!$D$5:$D$115,MATCH($C16,'Topic Plan'!$B$5:$B$115,0)),"")) | F16: =IF($C16="","",IFERROR(INDEX('Topic Plan'!$E$5:$E$115,MATCH($C16,'Topic Plan'!$B$5:$B$115,0)),"")) | V16: =IF(OR($A16="",$U16=""),"",IF($S16<>"",MAX(0,$S16-$U16),MAX(0,TODAY()-$U16))) | W16: =IF($A16="","",IF(OR($N16="Live",$N16="Retired"),"",TODAY()-MAX($O16,$P16,$Q16,$R16))) | Y16: =IF($A16="","",COUNTIFS('Issues Log'!$C$5:$C$504,$A16,'Issues Log'!$K$5:$K$504,"Open")+COUNTIFS('Issues Log'!$C$5:$C$504,$A16,'Issues Log'!$K$5:$K$504,"In progress"))
... D1004: =IF($C1004="","",IFERROR(INDEX('Topic Plan'!$C$5:$C$115,MATCH($C1004,'Topic Plan'!$B$5:$B$115,0)),"UNKNOWN TOPIC ID")) | E1004: =IF($C1004="","",IFERROR(INDEX('Topic Plan'!$D$5:$D$115,MATCH($C1004,'Topic Plan'!$B$5:$B$115,0)),"")) | F1004: =IF($C1004="","",IFERROR(INDEX('Topic Plan'!$E$5:$E$115,MATCH($C1004,'Topic Plan'!$B$5:$B$115,0)),"")) | V1004: =IF(OR($A1004="",$U1004=""),"",IF($S1004<>"",MAX(0,$S1004-$U1004),MAX(0,TODAY()-$U1004))) | W1004: =IF($A1004="","",IF(OR($N1004="Live",$N1004="Retired"),"",TODAY()-MAX($O1004,$P1004,$Q1004,$R1004))) | Y1004: =IF($A1004="","",COUNTIFS('Issues Log'!$C$5:$C$504,$A1004,'Issues Log'!$K$5:$K$504,"Open")+COUNTIFS('Issues Log'!$C$5:$C$504,$A1004,'Issues Log'!$K$5:$K$504,"In progress"))

Sheet Issues Log
A1: Issues Log
A2: Anything that blocks a chart entering the pool or casts doubt on one already in it. An answer-key dispute belongs here the day it is raised, not after it is settled.
A4: Issue ID | B4: Date raised | C4: Chart ID | D4: Topic ID | E4: Specialty | F4: Issue type | G4: Severity | H4: Description | I4: Raised by | J4: Owner | K4: Status | L4: Target resolution | M4: Date resolved | N4: Days open (auto) | O4: Overdue (auto) | P4: Resolution
N5: =IF($A5="","",IF($M5="",TODAY()-$B5,$M5-$B5)) | O5: =IF(OR($A5="",$L5=""),"",IF(OR($K5="Resolved",$K5="Will not fix"),"Closed",IF(TODAY()>$L5,"OVERDUE","On time")))
N6: =IF($A6="","",IF($M6="",TODAY()-$B6,$M6-$B6)) | O6: =IF(OR($A6="",$L6=""),"",IF(OR($K6="Resolved",$K6="Will not fix"),"Closed",IF(TODAY()>$L6,"OVERDUE","On time")))
N7: =IF($A7="","",IF($M7="",TODAY()-$B7,$M7-$B7)) | O7: =IF(OR($A7="",$L7=""),"",IF(OR($K7="Resolved",$K7="Will not fix"),"Closed",IF(TODAY()>$L7,"OVERDUE","On time")))
N8: =IF($A8="","",IF($M8="",TODAY()-$B8,$M8-$B8)) | O8: =IF(OR($A8="",$L8=""),"",IF(OR($K8="Resolved",$K8="Will not fix"),"Closed",IF(TODAY()>$L8,"OVERDUE","On time")))
N9: =IF($A9="","",IF($M9="",TODAY()-$B9,$M9-$B9)) | O9: =IF(OR($A9="",$L9=""),"",IF(OR($K9="Resolved",$K9="Will not fix"),"Closed",IF(TODAY()>$L9,"OVERDUE","On time")))
N10: =IF($A10="","",IF($M10="",TODAY()-$B10,$M10-$B10)) | O10: =IF(OR($A10="",$L10=""),"",IF(OR($K10="Resolved",$K10="Will not fix"),"Closed",IF(TODAY()>$L10,"OVERDUE","On time")))
N11: =IF($A11="","",IF($M11="",TODAY()-$B11,$M11-$B11)) | O11: =IF(OR($A11="",$L11=""),"",IF(OR($K11="Resolved",$K11="Will not fix"),"Closed",IF(TODAY()>$L11,"OVERDUE","On time")))
N12: =IF($A12="","",IF($M12="",TODAY()-$B12,$M12-$B12)) | O12: =IF(OR($A12="",$L12=""),"",IF(OR($K12="Resolved",$K12="Will not fix"),"Closed",IF(TODAY()>$L12,"OVERDUE","On time")))
N13: =IF($A13="","",IF($M13="",TODAY()-$B13,$M13-$B13)) | O13: =IF(OR($A13="",$L13=""),"",IF(OR($K13="Resolved",$K13="Will not fix"),"Closed",IF(TODAY()>$L13,"OVERDUE","On time")))
N14: =IF($A14="","",IF($M14="",TODAY()-$B14,$M14-$B14)) | O14: =IF(OR($A14="",$L14=""),"",IF(OR($K14="Resolved",$K14="Will not fix"),"Closed",IF(TODAY()>$L14,"OVERDUE","On time")))
N15: =IF($A15="","",IF($M15="",TODAY()-$B15,$M15-$B15)) | O15: =IF(OR($A15="",$L15=""),"",IF(OR($K15="Resolved",$K15="Will not fix"),"Closed",IF(TODAY()>$L15,"OVERDUE","On time")))
N16: =IF($A16="","",IF($M16="",TODAY()-$B16,$M16-$B16)) | O16: =IF(OR($A16="",$L16=""),"",IF(OR($K16="Resolved",$K16="Will not fix"),"Closed",IF(TODAY()>$L16,"OVERDUE","On time")))
... N504: =IF($A504="","",IF($M504="",TODAY()-$B504,$M504-$B504)) | O504: =IF(OR($A504="",$L504=""),"",IF(OR($K504="Resolved",$K504="Will not fix"),"Closed",IF(TODAY()>$L504,"OVERDUE","On time")))
A506: An answer-key issue is not an ordinary defect. A wrong key silently grades everyone against it, so a chart with a suspected key problem goes On hold in the register until the issue is closed, rather than staying live while the dispute runs.
A507: Days open counts to today while the issue is open and freezes at the resolution date once it closes, so the column is a live age and a historical duration in the same place.

Sheet Topic Plan
A1: Topic Plan — target against actual, topic by topic
A2: Targets come from the composition taxonomy. Everything from column I rightwards counts the register, so it is live the moment a chart is logged.
A4: Specialty | B4: Topic ID | C4: Topic | D4: Coverage category | E4: Build priority | F4: Difficulty skew | G4: Primary sourcing channel | H4: Target charts | I4: Rows logged | J4: Live | K4: In build | L4: On hold | M4: Retired | N4: % of target | O4: Gap to target | P4: Gap status (HC section 9) | Q4: Expected complete | R4: Days vs expected | S4: Open issues
A5: IP-DRG | B5: IPD-01 | C5: Vaginal delivery and complications of labour | D5: Medical DRGs | E5: P1 | F5: Complex-led | G5: C6 Customer escalations | H5: 35 | I5: =COUNTIFS('Chart Register'!$C$5:$C$1004,$B5) | J5: =COUNTIFS('Chart Register'!$C$5:$C$1004,$B5,'Chart Register'!$N$5:$N$1004,"Live") | K5: =I5-J5-L5-M5 | L5: =COUNTIFS('Chart Register'!$C$5:$C$1004,$B5,'Chart Register'!$N$5:$N$1004,"On hold") | M5: =COUNTIFS('Chart Register'!$C$5:$C$1004,$B5,'Chart Register'!$N$5:$N$1004,"Retired") | N5: =IF($H5=0,"NA",J5/$H5) | O5: =$H5-J5 | P5: =IF($H5=0,"NA",IF(J5>=$H5,"Complete",IF(J5/$H5>='Schedule Model'!$C$8,"At or above threshold","BELOW THRESHOLD — source now"))) | Q5: =IF('Schedule Model'!$G$12="NA","NA",INT('Schedule Model'!$C$5+0.050215*'Schedule Model'!$G$12*7)) | R5: =IF(OR($H5=0,NOT(ISNUMBER(Q5))),"NA",IF(J5>=$H5,"On target",IF(TODAY()<=Q5,"Not yet due",TODAY()-Q5))) | S5: =COUNTIFS('Issues Log'!$D$5:$D$504,$B5,'Issues Log'!$K$5:$K$504,"Open")+COUNTIFS('Issues Log'!$D$5:$D$504,$B5,'Issues Log'!$K$5:$K$504,"In progress")
A6: IP-DRG | B6: IPD-02 | C6: Normal newborn and newborn with condition | D6: Medical DRGs | E6: P1 | F6: Moderate-led | G6: C1 High error rate | H6: 28 | I6: =COUNTIFS('Chart Register'!$C$5:$C$1004,$B6) | J6: =COUNTIFS('Chart Register'!$C$5:$C$1004,$B6,'Chart Register'!$N$5:$N$1004,"Live") | K6: =I6-J6-L6-M6 | L6: =COUNTIFS('Chart Register'!$C$5:$C$1004,$B6,'Chart Register'!$N$5:$N$1004,"On hold") | M6: =COUNTIFS('Chart Register'!$C$5:$C$1004,$B6,'Chart Register'!$N$5:$N$1004,"Retired") | N6: =IF($H6=0,"NA",J6/$H6) | O6: =$H6-J6 | P6: =IF($H6=0,"NA",IF(J6>=$H6,"Complete",IF(J6/$H6>='Schedule Model'!$C$8,"At or above threshold","BELOW THRESHOLD — source now"))) | Q6: =IF('Schedule Model'!$G$12="NA","NA",INT('Schedule Model'!$C$5+0.090387*'Schedule Model'!$G$12*7)) | R6: =IF(OR($H6=0,NOT(ISNUMBER(Q6))),"NA",IF(J6>=$H6,"On target",IF(TODAY()<=Q6,"Not yet due",TODAY()-Q6))) | S6: =COUNTIFS('Issues Log'!$D$5:$D$504,$B6,'Issues Log'!$K$5:$K$504,"Open")+COUNTIFS('Issues Log'!$D$5:$D$504,$B6,'Issues Log'!$K$5:$K$504,"In progress")
A7: IP-DRG | B7: IPD-03 | C7: Neonatal and NICU admissions | D7: Medical DRGs | E7: P1 | F7: Complex-led | G7: C2 High dollar value | H7: 14 | I7: =COUNTIFS('Chart Register'!$C$5:$C$1004,$B7) | J7: =COUNTIFS('Chart Register'!$C$5:$C$1004,$B7,'Chart Register'!$N$5:$N$1004,"Live") | K7: =I7-J7-L7-M7 | L7: =COUNTIFS('Chart Register'!$C$5:$C$1004,$B7,'Chart Register'!$N$5:$N$1004,"On hold") | M7: =COUNTIFS('Chart Register'!$C$5:$C$1004,$B7,'Chart Register'!$N$5:$N$1004,"Retired") | N7: =IF($H7=0,"NA",J7/$H7) | O7: =$H7-J7 | P7: =IF($H7=0,"NA",IF(J7>=$H7,"Complete",IF(J7/$H7>='Schedule Model'!$C$8,"At or above threshold","BELOW THRESHOLD — source now"))) | Q7: =IF('Schedule Model'!$G$12="NA","NA",INT('Schedule Model'!$C$5+0.110473*'Schedule Model'!$G$12*7)) | R7: =IF(OR($H7=0,NOT(ISNUMBER(Q7))),"NA",IF(J7>=$H7,"On target",IF(TODAY()<=Q7,"Not yet due",TODAY()-Q7))) | S7: =COUNTIFS('Issues Log'!$D$5:$D$504,$B7,'Issues Log'!$K$5:$K$504,"Open")+COUNTIFS('Issues Log'!$D$5:$D$504,$B7,'Issues Log'!$K$5:$K$504,"In progress")
A8: IP-DRG | B8: IPD-04 | C8: Antepartum and postpartum medical admissions | D8: Medical DRGs | E8: P1 | F8: Complex-led | G8: C1 High error rate | H8: 14 | I8: =COUNTIFS('Chart Register'!$C$5:$C$1004,$B8) | J8: =COUNTIFS('Chart Register'!$C$5:$C$1004,$B8,'Chart Register'!$N$5:$N$1004,"Live") | K8: =I8-J8-L8-M8 | L8: =COUNTIFS('Chart Register'!$C$5:$C$1004,$B8,'Chart Register'!$N$5:$N$1004,"On hold") | M8: =COUNTIFS('Chart Register'!$C$5:$C$1004,$B8,'Chart Register'!$N$5:$N$1004,"Retired") | N8: =IF($H8=0,"NA",J8/$H8) | O8: =$H8-J8 | P8: =IF($H8=0,"NA",IF(J8>=$H8,"Complete",IF(J8/$H8>='Schedule Model'!$C$8,"At or above threshold","BELOW THRESHOLD — source now"))) | Q8: =IF('Schedule Model'!$G$12="NA","NA",INT('Schedule Model'!$C$5+0.13056*'Schedule Model'!$G$12*7)) | R8: =IF(OR($H8=0,NOT(ISNUMBER(Q8))),"NA",IF(J8>=$H8,"On target",IF(TODAY()<=Q8,"Not yet due",TODAY()-Q8))) | S8: =COUNTIFS('Issues Log'!$D$5:$D$504,$B8,'Issues Log'!$K$5:$K$504,"Open")+COUNTIFS('Issues Log'!$D$5:$D$504,$B8,'Issues Log'!$K$5:$K$504,"In progress")
A9: IP-DRG | B9: IPD-15 | C9: Caesarean delivery | D9: Surgical DRGs | E9: P1 | F9: Complex-led | G9: C1 High error rate | H9: 28 | I9: =COUNTIFS('Chart Register'!$C$5:$C$1004,$B9) | J9: =COUNTIFS('Chart Register'!$C$5:$C$1004,$B9,'Chart Register'!$N$5:$N$1004,"Live") | K9: =I9-J9-L9-M9 | L9: =COUNTIFS('Chart Register'!$C$5:$C$1004,$B9,'Chart Register'!$N$5:$N$1004,"On hold") | M9: =COUNTIFS('Chart Register'!$C$5:$C$1004,$B9,'Chart Register'!$N$5:$N$1004,"Retired") | N9: =IF($H9=0,"NA",J9/$H9) | O9: =$H9-J9 | P9: =IF($H9=0,"NA",IF(J9>=$H9,"Complete",IF(J9/$H9>='Schedule Model'!$C$8,"At or above threshold","BELOW THRESHOLD — source now"))) | Q9: =IF('Schedule Model'!$G$12="NA","NA",INT('Schedule Model'!$C$5+0.170732*'Schedule Model'!$G$12*7)) | R9: =IF(OR($H9=0,NOT(ISNUMBER(Q9))),"NA",IF(J9>=$H9,"On target",IF(TODAY()<=Q9,"Not yet due",TODAY()-Q9))) | S9: =COUNTIFS('Issues Log'!$D$5:$D$504,$B9,'Issues Log'!$K$5:$K$504,"Open")+COUNTIFS('Issues Log'!$D$5:$D$504,$B9,'Issues Log'!$K$5:$K$504,"In progress")
A10: IP-DRG | B10: IPD-16 | C10: Obstetric and postpartum surgical procedures | D10: Surgical DRGs | E10: P1 | F10: Complex-led | G10: C6 Customer escalations | H10: 14 | I10: =COUNTIFS('Chart Register'!$C$5:$C$1004,$B10) | J10: =COUNTIFS('Chart Register'!$C$5:$C$1004,$B10,'Chart Register'!$N$5:$N$1004,"Live") | K10: =I10-J10-L10-M10 | L10: =COUNTIFS('Chart Register'!$C$5:$C$1004,$B10,'Chart Register'!$N$5:$N$1004,"On hold") | M10: =COUNTIFS('Chart Register'!$C$5:$C$1004,$B10,'Chart Register'!$N$5:$N$1004,"Retired") | N10: =IF($H10=0,"NA",J10/$H10) | O10: =$H10-J10 | P10: =IF($H10=0,"NA",IF(J10>=$H10,"Complete",IF(J10/$H10>='Schedule Model'!$C$8,"At or above threshold","BELOW THRESHOLD — source now"))) | Q10: =IF('Schedule Model'!$G$12="NA","NA",INT('Schedule Model'!$C$5+0.190818*'Schedule Model'!$G$12*7)) | R10: =IF(OR($H10=0,NOT(ISNUMBER(Q10))),"NA",IF(J10>=$H10,"On target",IF(TODAY()<=Q10,"Not yet due",TODAY()-Q10))) | S10: =COUNTIFS('Issues Log'!$D$5:$D$504,$B10,'Issues Log'!$K$5:$K$504,"Open")+COUNTIFS('Issues Log'!$D$5:$D$504,$B10,'Issues Log'!$K$5:$K$504,"In progress")
A11: IP-DRG | B11: IPD-05 | C11: Digestive medical — GI bleed, pancreatitis, obstruction | D11: Medical DRGs | E11: P2 | F11: Moderate-led | G11: C1 High error rate | H11: 42 | I11: =COUNTIFS('Chart Register'!$C$5:$C$1004,$B11) | J11: =COUNTIFS('Chart Register'!$C$5:$C$1004,$B11,'Chart Register'!$N$5:$N$1004,"Live") | K11: =I11-J11-L11-M11 | L11: =COUNTIFS('Chart Register'!$C$5:$C$1004,$B11,'Chart Register'!$N$5:$N$1004,"On hold") | M11: =COUNTIFS('Chart Register'!$C$5:$C$1004,$B11,'Chart Register'!$N$5:$N$1004,"Retired") | N11: =IF($H11=0,"NA",J11/$H11) | O11: =$H11-J11 | P11: =IF($H11=0,"NA",IF(J11>=$H11,"Complete",IF(J11/$H11>='Schedule Model'!$C$8,"At or above threshold","BELOW THRESHOLD — source now"))) | Q11: =IF('Schedule Model'!$G$12="NA","NA",INT('Schedule Model'!$C$5+0.251076*'Schedule Model'!$G$12*7)) | R11: =IF(OR($H11=0,NOT(ISNUMBER(Q11))),"NA",IF(J11>=$H11,"On target",IF(TODAY()<=Q11,"Not yet due",TODAY()-Q11))) | S11: =COUNTIFS('Issues Log'!$D$5:$D$504,$B11,'Issues Log'!$K$5:$K$504,"Open")+COUNTIFS('Issues Log'!$D$5:$D$504,$B11,'Issues Log'!$K$5:$K$504,"In progress")
A12: IP-DRG | B12: IPD-06 | C12: Respiratory — pneumonia, COPD exacerbation, respiratory failure | D12: Medical DRGs | E12: P2 | F12: Moderate-led | G12: C1 High error rate | H12: 49 | I12: =COUNTIFS('Chart Register'!$C$5:$C$1004,$B12) | J12: =COUNTIFS('Chart Register'!$C$5:$C$1004,$B12,'Chart Register'!$N$5:$N$1004,"Live") | K12: =I12-J12-L12-M12 | L12: =COUNTIFS('Chart Register'!$C$5:$C$1004,$B12,'Chart Register'!$N$5:$N$1004,"On hold") | M12: =COUNTIFS('Chart Register'!$C$5:$C$1004,$B12,'Chart Register'!$N$5:$N$1004,"Retired") | N12: =IF($H12=0,"NA",J12/$H12) | O12: =$H12-J12 | P12: =IF($H12=0,"NA",IF(J12>=$H12,"Complete",IF(J12/$H12>='Schedule Model'!$C$8,"At or above threshold","BELOW THRESHOLD — source now"))) | Q12: =IF('Schedule Model'!$G$12="NA","NA",INT('Schedule Model'!$C$5+0.321377*'Schedule Model'!$G$12*7)) | R12: =IF(OR($H12=0,NOT(ISNUMBER(Q12))),"NA",IF(J12>=$H12,"On target",IF(TODAY()<=Q12,"Not yet due",TODAY()-Q12))) | S12: =COUNTIFS('Issues Log'!$D$5:$D$504,$B12,'Issues Log'!$K$5:$K$504,"Open")+COUNTIFS('Issues Log'!$D$5:$D$504,$B12,'Issues Log'!$K$5:$K$504,"In progress")
A13: IP-DRG | B13: IPD-07 | C13: Circulatory medical — heart failure, AMI, arrhythmia | D13: Medical DRGs | E13: P2 | F13: Moderate-led | G13: C5 DRGV trending PCS / DRG | H13: 42 | I13: =COUNTIFS('Chart Register'!$C$5:$C$1004,$B13) | J13: =COUNTIFS('Chart Register'!$C$5:$C$1004,$B13,'Chart Register'!$N$5:$N$1004,"Live") | K13: =I13-J13-L13-M13 | L13: =COUNTIFS('Chart Register'!$C$5:$C$1004,$B13,'Chart Register'!$N$5:$N$1004,"On hold") | M13: =COUNTIFS('Chart Register'!$C$5:$C$1004,$B13,'Chart Register'!$N$5:$N$1004,"Retired") | N13: =IF($H13=0,"NA",J13/$H13) | O13: =$H13-J13 | P13: =IF($H13=0,"NA",IF(J13>=$H13,"Complete",IF(J13/$H13>='Schedule Model'!$C$8,"At or above threshold","BELOW THRESHOLD — source now"))) | Q13: =IF('Schedule Model'!$G$12="NA","NA",INT('Schedule Model'!$C$5+0.381636*'Schedule Model'!$G$12*7)) | R13: =IF(OR($H13=0,NOT(ISNUMBER(Q13))),"NA",IF(J13>=$H13,"On target",IF(TODAY()<=Q13,"Not yet due",TODAY()-Q13))) | S13: =COUNTIFS('Issues Log'!$D$5:$D$504,$B13,'Issues Log'!$K$5:$K$504,"Open")+COUNTIFS('Issues Log'!$D$5:$D$504,$B13,'Issues Log'!$K$5:$K$504,"In progress")
A14: IP-DRG | B14: IPD-08 | C14: Sepsis, severe sepsis and septic shock | D14: Medical DRGs | E14: P2 | F14: Complex-led | G14: C1 High error rate | H14: 49 | I14: =COUNTIFS('Chart Register'!$C$5:$C$1004,$B14) | J14: =COUNTIFS('Chart Register'!$C$5:$C$1004,$B14,'Chart Register'!$N$5:$N$1004,"Live") | K14: =I14-J14-L14-M14 | L14: =COUNTIFS('Chart Register'!$C$5:$C$1004,$B14,'Chart Register'!$N$5:$N$1004,"On hold") | M14: =COUNTIFS('Chart Register'!$C$5:$C$1004,$B14,'Chart Register'!$N$5:$N$1004,"Retired") | N14: =IF($H14=0,"NA",J14/$H14) | O14: =$H14-J14 | P14: =IF($H14=0,"NA",IF(J14>=$H14,"Complete",IF(J14/$H14>='Schedule Model'!$C$8,"At or above threshold","BELOW THRESHOLD — source now"))) | Q14: =IF('Schedule Model'!$G$12="NA","NA",INT('Schedule Model'!$C$5+0.451937*'Schedule Model'!$G$12*7)) | R14: =IF(OR($H14=0,NOT(ISNUMBER(Q14))),"NA",IF(J14>=$H14,"On target",IF(TODAY()<=Q14,"Not yet due",TODAY()-Q14))) | S14: =COUNTIFS('Issues Log'!$D$5:$D$504,$B14,'Issues Log'!$K$5:$K$504,"Open")+COUNTIFS('Issues Log'!$D$5:$D$504,$B14,'Issues Log'!$K$5:$K$504,"In progress")
A15: IP-DRG | B15: IPD-09 | C15: Nervous system medical — CVA, TIA, intracranial haemorrhage | D15: Medical DRGs | E15: P2 | F15: Complex-led | G15: C2 High dollar value | H15: 28 | I15: =COUNTIFS('Chart Register'!$C$5:$C$1004,$B15) | J15: =COUNTIFS('Chart Register'!$C$5:$C$1004,$B15,'Chart Register'!$N$5:$N$1004,"Live") | K15: =I15-J15-L15-M15 | L15: =COUNTIFS('Chart Register'!$C$5:$C$1004,$B15,'Chart Register'!$N$5:$N$1004,"On hold") | M15: =COUNTIFS('Chart Register'!$C$5:$C$1004,$B15,'Chart Register'!$N$5:$N$1004,"Retired") | N15: =IF($H15=0,"NA",J15/$H15) | O15: =$H15-J15 | P15: =IF($H15=0,"NA",IF(J15>=$H15,"Complete",IF(J15/$H15>='Schedule Model'!$C$8,"At or above threshold","BELOW THRESHOLD — source now"))) | Q15: =IF('Schedule Model'!$G$12="NA","NA",INT('Schedule Model'!$C$5+0.492109*'Schedule Model'!$G$12*7)) | R15: =IF(OR($H15=0,NOT(ISNUMBER(Q15))),"NA",IF(J15>=$H15,"On target",IF(TODAY()<=Q15,"Not yet due",TODAY()-Q15))) | S15: =COUNTIFS('Issues Log'!$D$5:$D$504,$B15,'Issues Log'!$K$5:$K$504,"Open")+COUNTIFS('Issues Log'!$D$5:$D$504,$B15,'Issues Log'!$K$5:$K$504,"In progress")
A16: IP-DRG | B16: IPD-10 | C16: Kidney and urinary — AKI, CKD, UTI | D16: Medical DRGs | E16: P2 | F16: Moderate-led | G16: C1 High error rate | H16: 21 | I16: =COUNTIFS('Chart Register'!$C$5:$C$1004,$B16) | J16: =COUNTIFS('Chart Register'!$C$5:$C$1004,$B16,'Chart Register'!$N$5:$N$1004,"Live") | K16: =I16-J16-L16-M16 | L16: =COUNTIFS('Chart Register'!$C$5:$C$1004,$B16,'Chart Register'!$N$5:$N$1004,"On hold") | M16: =COUNTIFS('Chart Register'!$C$5:$C$1004,$B16,'Chart Register'!$N$5:$N$1004,"Retired") | N16: =IF($H16=0,"NA",J16/$H16) | O16: =$H16-J16 | P16: =IF($H16=0,"NA",IF(J16>=$H16,"Complete",IF(J16/$H16>='Schedule Model'!$C$8,"At or above threshold","BELOW THRESHOLD — source now"))) | Q16: =IF('Schedule Model'!$G$12="NA","NA",INT('Schedule Model'!$C$5+0.522238*'Schedule Model'!$G$12*7)) | R16: =IF(OR($H16=0,NOT(ISNUMBER(Q16))),"NA",IF(J16>=$H16,"On target",IF(TODAY()<=Q16,"Not yet due",TODAY()-Q16))) | S16: =COUNTIFS('Issues Log'!$D$5:$D$504,$B16,'Issues Log'!$K$5:$K$504,"Open")+COUNTIFS('Issues Log'!$D$5:$D$504,$B16,'Issues Log'!$K$5:$K$504,"In progress")
A17: IP-DRG | B17: IPD-11 | C17: Endocrine and metabolic — DKA, malnutrition, electrolyte disorders | D17: Medical DRGs | E17: P2 | F17: Complex-led | G17: C1 High error rate | H17: 21 | I17: =COUNTIFS('Chart Register'!$C$5:$C$1004,$B17) | J17: =COUNTIFS('Chart Register'!$C$5:$C$1004,$B17,'Chart Register'!$N$5:$N$1004,"Live") | K17: =I17-J17-L17-M17 | L17: =COUNTIFS('Chart Register'!$C$5:$C$1004,$B17,'Chart Register'!$N$5:$N$1004,"On hold") | M17: =COUNTIFS('Chart Register'!$C$5:$C$1004,$B17,'Chart Register'!$N$5:$N$1004,"Retired") | N17: =IF($H17=0,"NA",J17/$H17) | O17: =$H17-J17 | P17: =IF($H17=0,"NA",IF(J17>=$H17,"Complete",IF(J17/$H17>='Schedule Model'!$C$8,"At or above threshold","BELOW THRESHOLD — source now"))) | Q17: =IF('Schedule Model'!$G$12="NA","NA",INT('Schedule Model'!$C$5+0.552367*'Schedule Model'!$G$12*7)) | R17: =IF(OR($H17=0,NOT(ISNUMBER(Q17))),"NA",IF(J17>=$H17,"On target",IF(TODAY()<=Q17,"Not yet due",TODAY()-Q17))) | S17: =COUNTIFS('Issues Log'!$D$5:$D$504,$B17,'Issues Log'!$K$5:$K$504,"Open")+COUNTIFS('Issues Log'!$D$5:$D$504,$B17,'Issues Log'!$K$5:$K$504,"In progress")
A18: IP-DRG | B18: IPD-12 | C18: Haematology and oncology — medical admissions | D18: Medical DRGs | E18: P2 | F18: Complex-led | G18: C6 Customer escalations | H18: 21 | I18: =COUNTIFS('Chart Register'!$C$5:$C$1004,$B18) | J18: =COUNTIFS('Chart Register'!$C$5:$C$1004,$B18,'Chart Register'!$N$5:$N$1004,"Live") | K18: =I18-J18-L18-M18 | L18: =COUNTIFS('Chart Register'!$C$5:$C$1004,$B18,'Chart Register'!$N$5:$N$1004,"On hold") | M18: =COUNTIFS('Chart Register'!$C$5:$C$1004,$B18,'Chart Register'!$N$5:$N$1004,"Retired") | N18: =IF($H18=0,"NA",J18/$H18) | O18: =$H18-J18 | P18: =IF($H18=0,"NA",IF(J18>=$H18,"Complete",IF(J18/$H18>='Schedule Model'!$C$8,"At or above threshold","BELOW THRESHOLD — source now"))) | Q18: =IF('Schedule Model'!$G$12="NA","NA",INT('Schedule Model'!$C$5+0.582496*'Schedule Model'!$G$12*7)) | R18: =IF(OR($H18=0,NOT(ISNUMBER(Q18))),"NA",IF(J18>=$H18,"On target",IF(TODAY()<=Q18,"Not yet due",TODAY()-Q18))) | S18: =COUNTIFS('Issues Log'!$D$5:$D$504,$B18,'Issues Log'!$K$5:$K$504,"Open")+COUNTIFS('Issues Log'!$D$5:$D$504,$B18,'Issues Log'!$K$5:$K$504,"In progress")
A19: IP-DRG | B19: IPD-17 | C19: Digestive surgical — bowel resection, cholecystectomy, hernia repair | D19: Surgical DRGs | E19: P2 | F19: Moderate-led | G19: C8 Foundation | H19: 55 | I19: =COUNTIFS('Chart Register'!$C$5:$C$1004,$B19) | J19: =COUNTIFS('Chart Register'!$C$5:$C$1004,$B19,'Chart Register'!$N$5:$N$1004,"Live") | K19: =I19-J19-L19-M19 | L19: =COUNTIFS('Chart Register'!$C$5:$C$1004,$B19,'Chart Register'!$N$5:$N$1004,"On hold") | M19: =COUNTIFS('Chart Register'!$C$5:$C$1004,$B19,'Chart Register'!$N$5:$N$1004,"Retired") | N19: =IF($H19=0,"NA",J19/$H19) | O19: =$H19-J19 | P19: =IF($H19=0,"NA",IF(J19>=$H19,"Complete",IF(J19/$H19>='Schedule Model'!$C$8,"At or above threshold","BELOW THRESHOLD — source now"))) | Q19: =IF('Schedule Model'!$G$12="NA","NA",INT('Schedule Model'!$C$5+0.661406*'Schedule Model'!$G$12*7)) | R19: =IF(OR($H19=0,NOT(ISNUMBER(Q19))),"NA",IF(J19>=$H19,"On target",IF(TODAY()<=Q19,"Not yet due",TODAY()-Q19))) | S19: =COUNTIFS('Issues Log'!$D$5:$D$504,$B19,'Issues Log'!$K$5:$K$504,"Open")+COUNTIFS('Issues Log'!$D$5:$D$504,$B19,'Issues Log'!$K$5:$K$504,"In progress")
A20: IP-DRG | B20: IPD-18 | C20: Cardiovascular surgical — CABG, valve, PCI, EP procedures | D20: Surgical DRGs | E20: P2 | F20: Complex-led | G20: C2 High dollar value | H20: 55 | I20: =COUNTIFS('Chart Register'!$C$5:$C$1004,$B20) | J20: =COUNTIFS('Chart Register'!$C$5:$C$1004,$B20,'Chart Register'!$N$5:$N$1004,"Live") | K20: =I20-J20-L20-M20 | L20: =COUNTIFS('Chart Register'!$C$5:$C$1004,$B20,'Chart Register'!$N$5:$N$1004,"On hold") | M20: =COUNTIFS('Chart Register'!$C$5:$C$1004,$B20,'Chart Register'!$N$5:$N$1004,"Retired") | N20: =IF($H20=0,"NA",J20/$H20) | O20: =$H20-J20 | P20: =IF($H20=0,"NA",IF(J20>=$H20,"Complete",IF(J20/$H20>='Schedule Model'!$C$8,"At or above threshold","BELOW THRESHOLD — source now"))) | Q20: =IF('Schedule Model'!$G$12="NA","NA",INT('Schedule Model'!$C$5+0.740316*'Schedule Model'!$G$12*7)) | R20: =IF(OR($H20=0,NOT(ISNUMBER(Q20))),"NA",IF(J20>=$H20,"On target",IF(TODAY()<=Q20,"Not yet due",TODAY()-Q20))) | S20: =COUNTIFS('Issues Log'!$D$5:$D$504,$B20,'Issues Log'!$K$5:$K$504,"Open")+COUNTIFS('Issues Log'!$D$5:$D$504,$B20,'Issues Log'!$K$5:$K$504,"In progress")
A21: IP-DRG | B21: IPD-19 | C21: Respiratory surgical — thoracotomy, tracheostomy, lung resection | D21: Surgical DRGs | E21: P2 | F21: Complex-led | G21: C5 DRGV trending PCS / DRG | H21: 21 | I21: =COUNTIFS('Chart Register'!$C$5:$C$1004,$B21) | J21: =COUNTIFS('Chart Register'!$C$5:$C$1004,$B21,'Chart Register'!$N$5:$N$1004,"Live") | K21: =I21-J21-L21-M21 | L21: =COUNTIFS('Chart Register'!$C$5:$C$1004,$B21,'Chart Register'!$N$5:$N$1004,"On hold") | M21: =COUNTIFS('Chart Register'!$C$5:$C$1004,$B21,'Chart Register'!$N$5:$N$1004,"Retired") | N21: =IF($H21=0,"NA",J21/$H21) | O21: =$H21-J21 | P21: =IF($H21=0,"NA",IF(J21>=$H21,"Complete",IF(J21/$H21>='Schedule Model'!$C$8,"At or above threshold","BELOW THRESHOLD — source now"))) | Q21: =IF('Schedule Model'!$G$12="NA","NA",INT('Schedule Model'!$C$5+0.770445*'Schedule Model'!$G$12*7)) | R21: =IF(OR($H21=0,NOT(ISNUMBER(Q21))),"NA",IF(J21>=$H21,"On target",IF(TODAY()<=Q21,"Not yet due",TODAY()-Q21))) | S21: =COUNTIFS('Issues Log'!$D$5:$D$504,$B21,'Issues Log'!$K$5:$K$504,"Open")+COUNTIFS('Issues Log'!$D$5:$D$504,$B21,'Issues Log'!$K$5:$K$504,"In progress")
A22: IP-DRG | B22: IPD-20 | C22: Musculoskeletal — joint replacement, spinal fusion, fracture fixation | D22: Surgical DRGs | E22: P2 | F22: Moderate-led | G22: C5 DRGV trending PCS / DRG | H22: 62 | I22: =COUNTIFS('Chart Register'!$C$5:$C$1004,$B22) | J22: =COUNTIFS('Chart Register'!$C$5:$C$1004,$B22,'Chart Register'!$N$5:$N$1004,"Live") | K22: =I22-J22-L22-M22 | L22: =COUNTIFS('Chart Register'!$C$5:$C$1004,$B22,'Chart Register'!$N$5:$N$1004,"On hold") | M22: =COUNTIFS('Chart Register'!$C$5:$C$1004,$B22,'Chart Register'!$N$5:$N$1004,"Retired") | N22: =IF($H22=0,"NA",J22/$H22) | O22: =$H22-J22 | P22: =IF($H22=0,"NA",IF(J22>=$H22,"Complete",IF(J22/$H22>='Schedule Model'!$C$8,"At or above threshold","BELOW THRESHOLD — source now"))) | Q22: =IF('Schedule Model'!$G$12="NA","NA",INT('Schedule Model'!$C$5+0.859397*'Schedule Model'!$G$12*7)) | R22: =IF(OR($H22=0,NOT(ISNUMBER(Q22))),"NA",IF(J22>=$H22,"On target",IF(TODAY()<=Q22,"Not yet due",TODAY()-Q22))) | S22: =COUNTIFS('Issues Log'!$D$5:$D$504,$B22,'Issues Log'!$K$5:$K$504,"Open")+COUNTIFS('Issues Log'!$D$5:$D$504,$B22,'Issues Log'!$K$5:$K$504,"In progress")
A23: IP-DRG | B23: IPD-21 | C23: Nervous system surgical — craniotomy, shunt, spine decompression | D23: Surgical DRGs | E23: P2 | F23: Complex-led | G23: C2 High dollar value | H23: 28 | I23: =COUNTIFS('Chart Register'!$C$5:$C$1004,$B23) | J23: =COUNTIFS('Chart Register'!$C$5:$C$1004,$B23,'Chart Register'!$N$5:$N$1004,"Live") | K23: =I23-J23-L23-M23 | L23: =COUNTIFS('Chart Register'!$C$5:$C$1004,$B23,'Chart Register'!$N$5:$N$1004,"On hold") | M23: =COUNTIFS('Chart Register'!$C$5:$C$1004,$B23,'Chart Register'!$N$5:$N$1004,"Retired") | N23: =IF($H23=0,"NA",J23/$H23) | O23: =$H23-J23 | P23: =IF($H23=0,"NA",IF(J23>=$H23,"Complete",IF(J23/$H23>='Schedule Model'!$C$8,"At or above threshold","BELOW THRESHOLD — source now"))) | Q23: =IF('Schedule Model'!$G$12="NA","NA",INT('Schedule Model'!$C$5+0.89957*'Schedule Model'!$G$12*7)) | R23: =IF(OR($H23=0,NOT(ISNUMBER(Q23))),"NA",IF(J23>=$H23,"On target",IF(TODAY()<=Q23,"Not yet due",TODAY()-Q23))) | S23: =COUNTIFS('Issues Log'!$D$5:$D$504,$B23,'Issues Log'!$K$5:$K$504,"Open")+COUNTIFS('Issues Log'!$D$5:$D$504,$B23,'Issues Log'!$K$5:$K$504,"In progress")
A24: IP-DRG | B24: IPD-22 | C24: Genitourinary surgical | D24: Surgical DRGs | E24: P2 | F24: Moderate-led | G24: C8 Foundation | H24: 21 | I24: =COUNTIFS('Chart Register'!$C$5:$C$1004,$B24) | J24: =COUNTIFS('Chart Register'!$C$5:$C$1004,$B24,'Chart Register'!$N$5:$N$1004,"Live") | K24: =I24-J24-L24-M24 | L24: =COUNTIFS('Chart Register'!$C$5:$C$1004,$B24,'Chart Register'!$N$5:$N$1004,"On hold") | M24: =COUNTIFS('Chart Register'!$C$5:$C$1004,$B24,'Chart Register'!$N$5:$N$1004,"Retired") | N24: =IF($H24=0,"NA",J24/$H24) | O24: =$H24-J24 | P24: =IF($H24=0,"NA",IF(J24>=$H24,"Complete",IF(J24/$H24>='Schedule Model'!$C$8,"At or above threshold","BELOW THRESHOLD — source now"))) | Q24: =IF('Schedule Model'!$G$12="NA","NA",INT('Schedule Model'!$C$5+0.929699*'Schedule Model'!$G$12*7)) | R24: =IF(OR($H24=0,NOT(ISNUMBER(Q24))),"NA",IF(J24>=$H24,"On target",IF(TODAY()<=Q24,"Not yet due",TODAY()-Q24))) | S24: =COUNTIFS('Issues Log'!$D$5:$D$504,$B24,'Issues Log'!$K$5:$K$504,"Open")+COUNTIFS('Issues Log'!$D$5:$D$504,$B24,'Issues Log'!$K$5:$K$504,"In progress")
A25: IP-DRG | B25: IPD-13 | C25: Mental health and substance use | D25: Medical DRGs | E25: P3 | F25: Basic-led | G25: C8 Foundation | H25: 14 | I25: =COUNTIFS('Chart Register'!$C$5:$C$1004,$B25) | J25: =COUNTIFS('Chart Register'!$C$5:$C$1004,$B25,'Chart Register'!$N$5:$N$1004,"Live") | K25: =I25-J25-L25-M25 | L25: =COUNTIFS('Chart Register'!$C$5:$C$1004,$B25,'Chart Register'!$N$5:$N$1004,"On hold") | M25: =COUNTIFS('Chart Register'!$C$5:$C$1004,$B25,'Chart Register'!$N$5:$N$1004,"Retired") | N25: =IF($H25=0,"NA",J25/$H25) | O25: =$H25-J25 | P25: =IF($H25=0,"NA",IF(J25>=$H25,"Complete",IF(J25/$H25>='Schedule Model'!$C$8,"At or above threshold","BELOW THRESHOLD — source now"))) | Q25: =IF('Schedule Model'!$G$12="NA","NA",INT('Schedule Model'!$C$5+0.949785*'Schedule Model'!$G$12*7)) | R25: =IF(OR($H25=0,NOT(ISNUMBER(Q25))),"NA",IF(J25>=$H25,"On target",IF(TODAY()<=Q25,"Not yet due",TODAY()-Q25))) | S25: =COUNTIFS('Issues Log'!$D$5:$D$504,$B25,'Issues Log'!$K$5:$K$504,"Open")+COUNTIFS('Issues Log'!$D$5:$D$504,$B25,'Issues Log'!$K$5:$K$504,"In progress")
A26: IP-DRG | B26: IPD-14 | C26: Other infectious disease | D26: Medical DRGs | E26: P3 | F26: Moderate-led | G26: C8 Foundation | H26: 7 | I26: =COUNTIFS('Chart Register'!$C$5:$C$1004,$B26) | J26: =COUNTIFS('Chart Register'!$C$5:$C$1004,$B26,'Chart Register'!$N$5:$N$1004,"Live") | K26: =I26-J26-L26-M26 | L26: =COUNTIFS('Chart Register'!$C$5:$C$1004,$B26,'Chart Register'!$N$5:$N$1004,"On hold") | M26: =COUNTIFS('Chart Register'!$C$5:$C$1004,$B26,'Chart Register'!$N$5:$N$1004,"Retired") | N26: =IF($H26=0,"NA",J26/$H26) | O26: =$H26-J26 | P26: =IF($H26=0,"NA",IF(J26>=$H26,"Complete",IF(J26/$H26>='Schedule Model'!$C$8,"At or above threshold","BELOW THRESHOLD — source now"))) | Q26: =IF('Schedule Model'!$G$12="NA","NA",INT('Schedule Model'!$C$5+0.959828*'Schedule Model'!$G$12*7)) | R26: =IF(OR($H26=0,NOT(ISNUMBER(Q26))),"NA",IF(J26>=$H26,"On target",IF(TODAY()<=Q26,"Not yet due",TODAY()-Q26))) | S26: =COUNTIFS('Issues Log'!$D$5:$D$504,$B26,'Issues Log'!$K$5:$K$504,"Open")+COUNTIFS('Issues Log'!$D$5:$D$504,$B26,'Issues Log'!$K$5:$K$504,"In progress")
A27: IP-DRG | B27: IPD-23 | C27: Vascular access and device procedures — PICC, pacemaker, dialysis catheter | D27: Surgical DRGs | E27: P3 | F27: Moderate-led | G27: C6 Customer escalations | H27: 14 | I27: =COUNTIFS('Chart Register'!$C$5:$C$1004,$B27) | J27: =COUNTIFS('Chart Register'!$C$5:$C$1004,$B27,'Chart Register'!$N$5:$N$1004,"Live") | K27: =I27-J27-L27-M27 | L27: =COUNTIFS('Chart Register'!$C$5:$C$1004,$B27,'Chart Register'!$N$5:$N$1004,"On hold") | M27: =COUNTIFS('Chart Register'!$C$5:$C$1004,$B27,'Chart Register'!$N$5:$N$1004,"Retired") | N27: =IF($H27=0,"NA",J27/$H27) | O27: =$H27-J27 | P27: =IF($H27=0,"NA",IF(J27>=$H27,"Complete",IF(J27/$H27>='Schedule Model'!$C$8,"At or above threshold","BELOW THRESHOLD — source now"))) | Q27: =IF('Schedule Model'!$G$12="NA","NA",INT('Schedule Model'!$C$5+0.979914*'Schedule Model'!$G$12*7)) | R27: =IF(OR($H27=0,NOT(ISNUMBER(Q27))),"NA",IF(J27>=$H27,"On target",IF(TODAY()<=Q27,"Not yet due",TODAY()-Q27))) | S27: =COUNTIFS('Issues Log'!$D$5:$D$504,$B27,'Issues Log'!$K$5:$K$504,"Open")+COUNTIFS('Issues Log'!$D$5:$D$504,$B27,'Issues Log'!$K$5:$K$504,"In progress")
A28: IP-DRG | B28: IPD-24 | C28: Transplant and other high-weight DRGs | D28: Surgical DRGs | E28: P3 | F28: Complex-led | G28: C2 High dollar value | H28: 7 | I28: =COUNTIFS('Chart Register'!$C$5:$C$1004,$B28) | J28: =COUNTIFS('Chart Register'!$C$5:$C$1004,$B28,'Chart Register'!$N$5:$N$1004,"Live") | K28: =I28-J28-L28-M28 | L28: =COUNTIFS('Chart Register'!$C$5:$C$1004,$B28,'Chart Register'!$N$5:$N$1004,"On hold") | M28: =COUNTIFS('Chart Register'!$C$5:$C$1004,$B28,'Chart Register'!$N$5:$N$1004,"Retired") | N28: =IF($H28=0,"NA",J28/$H28) | O28: =$H28-J28 | P28: =IF($H28=0,"NA",IF(J28>=$H28,"Complete",IF(J28/$H28>='Schedule Model'!$C$8,"At or above threshold","BELOW THRESHOLD — source now"))) | Q28: =IF('Schedule Model'!$G$12="NA","NA",INT('Schedule Model'!$C$5+0.989957*'Schedule Model'!$G$12*7)) | R28: =IF(OR($H28=0,NOT(ISNUMBER(Q28))),"NA",IF(J28>=$H28,"On target",IF(TODAY()<=Q28,"Not yet due",TODAY()-Q28))) | S28: =COUNTIFS('Issues Log'!$D$5:$D$504,$B28,'Issues Log'!$K$5:$K$504,"Open")+COUNTIFS('Issues Log'!$D$5:$D$504,$B28,'Issues Log'!$K$5:$K$504,"In progress")
A29: IP-DRG | B29: IPD-25 | C29: Multiple significant trauma and burns | D29: Surgical DRGs | E29: P3 | F29: Complex-led | G29: C2 High dollar value | H29: 7 | I29: =COUNTIFS('Chart Register'!$C$5:$C$1004,$B29) | J29: =COUNTIFS('Chart Register'!$C$5:$C$1004,$B29,'Chart Register'!$N$5:$N$1004,"Live") | K29: =I29-J29-L29-M29 | L29: =COUNTIFS('Chart Register'!$C$5:$C$1004,$B29,'Chart Register'!$N$5:$N$1004,"On hold") | M29: =COUNTIFS('Chart Register'!$C$5:$C$1004,$B29,'Chart Register'!$N$5:$N$1004,"Retired") | N29: =IF($H29=0,"NA",J29/$H29) | O29: =$H29-J29 | P29: =IF($H29=0,"NA",IF(J29>=$H29,"Complete",IF(J29/$H29>='Schedule Model'!$C$8,"At or above threshold","BELOW THRESHOLD — source now"))) | Q29: =IF('Schedule Model'!$G$12="NA","NA",INT('Schedule Model'!$C$5+1.0*'Schedule Model'!$G$12*7)) | R29: =IF(OR($H29=0,NOT(ISNUMBER(Q29))),"NA",IF(J29>=$H29,"On target",IF(TODAY()<=Q29,"Not yet due",TODAY()-Q29))) | S29: =COUNTIFS('Issues Log'!$D$5:$D$504,$B29,'Issues Log'!$K$5:$K$504,"Open")+COUNTIFS('Issues Log'!$D$5:$D$504,$B29,'Issues Log'!$K$5:$K$504,"In progress")
A30: ED Facility | B30: EDF-01 | C30: Minor presentations and rechecks (99281 / 99282) | D30: Levels 1–2 | E30: P2 | F30: Basic-led | G30: C8 Foundation | H30: 70 | I30: =COUNTIFS('Chart Register'!$C$5:$C$1004,$B30) | J30: =COUNTIFS('Chart Register'!$C$5:$C$1004,$B30,'Chart Register'!$N$5:$N$1004,"Live") | K30: =I30-J30-L30-M30 | L30: =COUNTIFS('Chart Register'!$C$5:$C$1004,$B30,'Chart Register'!$N$5:$N$1004,"On hold") | M30: =COUNTIFS('Chart Register'!$C$5:$C$1004,$B30,'Chart Register'!$N$5:$N$1004,"Retired") | N30: =IF($H30=0,"NA",J30/$H30) | O30: =$H30-J30 | P30: =IF($H30=0,"NA",IF(J30>=$H30,"Complete",IF(J30/$H30>='Schedule Model'!$C$8,"At or above threshold","BELOW THRESHOLD — source now"))) | Q30: =IF('Schedule Model'!$G$13="NA","NA",INT('Schedule Model'!$C$5+0.1*'Schedule Model'!$G$13*7)) | R30: =IF(OR($H30=0,NOT(ISNUMBER(Q30))),"NA",IF(J30>=$H30,"On target",IF(TODAY()<=Q30,"Not yet due",TODAY()-Q30))) | S30: =COUNTIFS('Issues Log'!$D$5:$D$504,$B30,'Issues Log'!$K$5:$K$504,"Open")+COUNTIFS('Issues Log'!$D$5:$D$504,$B30,'Issues Log'!$K$5:$K$504,"In progress")
A31: ED Facility | B31: EDF-03 | C31: Low-acuity visits with an ED procedure | D31: Levels 1–2 | E31: P2 | F31: Basic-led | G31: C1 High error rate | H31: 35 | I31: =COUNTIFS('Chart Register'!$C$5:$C$1004,$B31) | J31: =COUNTIFS('Chart Register'!$C$5:$C$1004,$B31,'Chart Register'!$N$5:$N$1004,"Live") | K31: =I31-J31-L31-M31 | L31: =COUNTIFS('Chart Register'!$C$5:$C$1004,$B31,'Chart Register'!$N$5:$N$1004,"On hold") | M31: =COUNTIFS('Chart Register'!$C$5:$C$1004,$B31,'Chart Register'!$N$5:$N$1004,"Retired") | N31: =IF($H31=0,"NA",J31/$H31) | O31: =$H31-J31 | P31: =IF($H31=0,"NA",IF(J31>=$H31,"Complete",IF(J31/$H31>='Schedule Model'!$C$8,"At or above threshold","BELOW THRESHOLD — source now"))) | Q31: =IF('Schedule Model'!$G$13="NA","NA",INT('Schedule Model'!$C$5+0.15*'Schedule Model'!$G$13*7)) | R31: =IF(OR($H31=0,NOT(ISNUMBER(Q31))),"NA",IF(J31>=$H31,"On target",IF(TODAY()<=Q31,"Not yet due",TODAY()-Q31))) | S31: =COUNTIFS('Issues Log'!$D$5:$D$504,$B31,'Issues Log'!$K$5:$K$504,"Open")+COUNTIFS('Issues Log'!$D$5:$D$504,$B31,'Issues Log'!$K$5:$K$504,"In progress")
A32: ED Facility | B32: EDF-04 | C32: Moderate medical presentations — URI, UTI, gastroenteritis | D32: Level 3 | E32: P2 | F32: Basic-led | G32: C8 Foundation | H32: 70 | I32: =COUNTIFS('Chart Register'!$C$5:$C$1004,$B32) | J32: =COUNTIFS('Chart Register'!$C$5:$C$1004,$B32,'Chart Register'!$N$5:$N$1004,"Live") | K32: =I32-J32-L32-M32 | L32: =COUNTIFS('Chart Register'!$C$5:$C$1004,$B32,'Chart Register'!$N$5:$N$1004,"On hold") | M32: =COUNTIFS('Chart Register'!$C$5:$C$1004,$B32,'Chart Register'!$N$5:$N$1004,"Retired") | N32: =IF($H32=0,"NA",J32/$H32) | O32: =$H32-J32 | P32: =IF($H32=0,"NA",IF(J32>=$H32,"Complete",IF(J32/$H32>='Schedule Model'!$C$8,"At or above threshold","BELOW THRESHOLD — source now"))) | Q32: =IF('Schedule Model'!$G$13="NA","NA",INT('Schedule Model'!$C$5+0.25*'Schedule Model'!$G$13*7)) | R32: =IF(OR($H32=0,NOT(ISNUMBER(Q32))),"NA",IF(J32>=$H32,"On target",IF(TODAY()<=Q32,"Not yet due",TODAY()-Q32))) | S32: =COUNTIFS('Issues Log'!$D$5:$D$504,$B32,'Issues Log'!$K$5:$K$504,"Open")+COUNTIFS('Issues Log'!$D$5:$D$504,$B32,'Issues Log'!$K$5:$K$504,"In progress")
A33: ED Facility | B33: EDF-05 | C33: Minor trauma and wound repair | D33: Level 3 | E33: P2 | F33: Moderate-led | G33: C1 High error rate | H33: 56 | I33: =COUNTIFS('Chart Register'!$C$5:$C$1004,$B33) | J33: =COUNTIFS('Chart Register'!$C$5:$C$1004,$B33,'Chart Register'!$N$5:$N$1004,"Live") | K33: =I33-J33-L33-M33 | L33: =COUNTIFS('Chart Register'!$C$5:$C$1004,$B33,'Chart Register'!$N$5:$N$1004,"On hold") | M33: =COUNTIFS('Chart Register'!$C$5:$C$1004,$B33,'Chart Register'!$N$5:$N$1004,"Retired") | N33: =IF($H33=0,"NA",J33/$H33) | O33: =$H33-J33 | P33: =IF($H33=0,"NA",IF(J33>=$H33,"Complete",IF(J33/$H33>='Schedule Model'!$C$8,"At or above threshold","BELOW THRESHOLD — source now"))) | Q33: =IF('Schedule Model'!$G$13="NA","NA",INT('Schedule Model'!$C$5+0.33*'Schedule Model'!$G$13*7)) | R33: =IF(OR($H33=0,NOT(ISNUMBER(Q33))),"NA",IF(J33>=$H33,"On target",IF(TODAY()<=Q33,"Not yet due",TODAY()-Q33))) | S33: =COUNTIFS('Issues Log'!$D$5:$D$504,$B33,'Issues Log'!$K$5:$K$504,"Open")+COUNTIFS('Issues Log'!$D$5:$D$504,$B33,'Issues Log'!$K$5:$K$504,"In progress")
A34: ED Facility | B34: EDF-06 | C34: Orthopaedic injury — sprain, simple fracture, splinting | D34: Level 3 | E34: P2 | F34: Moderate-led | G34: C1 High error rate | H34: 49 | I34: =COUNTIFS('Chart Register'!$C$5:$C$1004,$B34) | J34: =COUNTIFS('Chart Register'!$C$5:$C$1004,$B34,'Chart Register'!$N$5:$N$1004,"Live") | K34: =I34-J34-L34-M34 | L34: =COUNTIFS('Chart Register'!$C$5:$C$1004,$B34,'Chart Register'!$N$5:$N$1004,"On hold") | M34: =COUNTIFS('Chart Register'!$C$5:$C$1004,$B34,'Chart Register'!$N$5:$N$1004,"Retired") | N34: =IF($H34=0,"NA",J34/$H34) | O34: =$H34-J34 | P34: =IF($H34=0,"NA",IF(J34>=$H34,"Complete",IF(J34/$H34>='Schedule Model'!$C$8,"At or above threshold","BELOW THRESHOLD — source now"))) | Q34: =IF('Schedule Model'!$G$13="NA","NA",INT('Schedule Model'!$C$5+0.4*'Schedule Model'!$G$13*7)) | R34: =IF(OR($H34=0,NOT(ISNUMBER(Q34))),"NA",IF(J34>=$H34,"On target",IF(TODAY()<=Q34,"Not yet due",TODAY()-Q34))) | S34: =COUNTIFS('Issues Log'!$D$5:$D$504,$B34,'Issues Log'!$K$5:$K$504,"Open")+COUNTIFS('Issues Log'!$D$5:$D$504,$B34,'Issues Log'!$K$5:$K$504,"In progress")
A35: ED Facility | B35: EDF-07 | C35: Infusion and injection administration visits | D35: Level 3 | E35: P2 | F35: Moderate-led | G35: C7 Denial trends | H35: 35 | I35: =COUNTIFS('Chart Register'!$C$5:$C$1004,$B35) | J35: =COUNTIFS('Chart Register'!$C$5:$C$1004,$B35,'Chart Register'!$N$5:$N$1004,"Live") | K35: =I35-J35-L35-M35 | L35: =COUNTIFS('Chart Register'!$C$5:$C$1004,$B35,'Chart Register'!$N$5:$N$1004,"On hold") | M35: =COUNTIFS('Chart Register'!$C$5:$C$1004,$B35,'Chart Register'!$N$5:$N$1004,"Retired") | N35: =IF($H35=0,"NA",J35/$H35) | O35: =$H35-J35 | P35: =IF($H35=0,"NA",IF(J35>=$H35,"Complete",IF(J35/$H35>='Schedule Model'!$C$8,"At or above threshold","BELOW THRESHOLD — source now"))) | Q35: =IF('Schedule Model'!$G$13="NA","NA",INT('Schedule Model'!$C$5+0.45*'Schedule Model'!$G$13*7)) | R35: =IF(OR($H35=0,NOT(ISNUMBER(Q35))),"NA",IF(J35>=$H35,"On target",IF(TODAY()<=Q35,"Not yet due",TODAY()-Q35))) | S35: =COUNTIFS('Issues Log'!$D$5:$D$504,$B35,'Issues Log'!$K$5:$K$504,"Open")+COUNTIFS('Issues Log'!$D$5:$D$504,$B35,'Issues Log'!$K$5:$K$504,"In progress")
A36: ED Facility | B36: EDF-08 | C36: Abdominal and chest pain workups | D36: Level 4 | E36: P2 | F36: Moderate-led | G36: C1 High error rate | H36: 63 | I36: =COUNTIFS('Chart Register'!$C$5:$C$1004,$B36) | J36: =COUNTIFS('Chart Register'!$C$5:$C$1004,$B36,'Chart Register'!$N$5:$N$1004,"Live") | K36: =I36-J36-L36-M36 | L36: =COUNTIFS('Chart Register'!$C$5:$C$1004,$B36,'Chart Register'!$N$5:$N$1004,"On hold") | M36: =COUNTIFS('Chart Register'!$C$5:$C$1004,$B36,'Chart Register'!$N$5:$N$1004,"Retired") | N36: =IF($H36=0,"NA",J36/$H36) | O36: =$H36-J36 | P36: =IF($H36=0,"NA",IF(J36>=$H36,"Complete",IF(J36/$H36>='Schedule Model'!$C$8,"At or above threshold","BELOW THRESHOLD — source now"))) | Q36: =IF('Schedule Model'!$G$13="NA","NA",INT('Schedule Model'!$C$5+0.54*'Schedule Model'!$G$13*7)) | R36: =IF(OR($H36=0,NOT(ISNUMBER(Q36))),"NA",IF(J36>=$H36,"On target",IF(TODAY()<=Q36,"Not yet due",TODAY()-Q36))) | S36: =COUNTIFS('Issues Log'!$D$5:$D$504,$B36,'Issues Log'!$K$5:$K$504,"Open")+COUNTIFS('Issues Log'!$D$5:$D$504,$B36,'Issues Log'!$K$5:$K$504,"In progress")
